Workbook
Name tabMain: RESULTS!$A$1:$JA$76

Sheet Leaderboard
A1: Rank | B1: Name | C1: Points | D1: Correct Scores | E1: Correct Results
A2: {=_xlfn.LET( _xlpm.names,TRANSPOSE(_xlfn.CHOOSECOLS(RESULTS!I76:ZZ76,_xlfn.SEQUENCE(1,85,1,3))), _xlpm.points,TRANSPOSE(_xlfn.CHOOSECOLS(RESULTS!I75:ZZ75,_xlfn.SEQUENCE(1,85,1,3))), _xlpm.table,_xlfn.HSTACK(_xlpm.names,_xlpm.points), _xlpm.filtered,_xlfn._xlws.FILTER(_xlpm.table,INDEX(_xlpm.table,,1)<>"Name"), _xlpm.sorted,_xlfn.SORTBY(_xlpm.filtered,INDEX(_xlpm.filtered,,2),-1), _xlfn.HSTACK(_xlfn.SEQUENCE(ROWS(_xlpm.sorted)),_xlpm.sorted) )} -> #VALUE! | D2: =IF(B2="","",COUNTIF(_xlfn.XLOOKUP(B2,RESULTS!$I$76:$ZZ$76,RESULTS!$I$3:$ZZ$74),3)) | E2: =IF(B2="","",COUNTIF(_xlfn.XLOOKUP(B2,RESULTS!$I$76:$ZZ$76,RESULTS!$I$3:$ZZ$74),1))
D3: =IF(B3="","",COUNTIF(_xlfn.XLOOKUP(B3,RESULTS!$I$76:$ZZ$76,RESULTS!$I$3:$ZZ$74),3)) | E3: =IF(B3="","",COUNTIF(_xlfn.XLOOKUP(B3,RESULTS!$I$76:$ZZ$76,RESULTS!$I$3:$ZZ$74),1))
D4: =IF(B4="","",COUNTIF(_xlfn.XLOOKUP(B4,RESULTS!$I$76:$ZZ$76,RESULTS!$I$3:$ZZ$74),3)) | E4: =IF(B4="","",COUNTIF(_xlfn.XLOOKUP(B4,RESULTS!$I$76:$ZZ$76,RESULTS!$I$3:$ZZ$74),1))
D5: =IF(B5="","",COUNTIF(_xlfn.XLOOKUP(B5,RESULTS!$I$76:$ZZ$76,RESULTS!$I$3:$ZZ$74),3)) | E5: =IF(B5="","",COUNTIF(_xlfn.XLOOKUP(B5,RESULTS!$I$76:$ZZ$76,RESULTS!$I$3:$ZZ$74),1))
D6: =IF(B6="","",COUNTIF(_xlfn.XLOOKUP(B6,RESULTS!$I$76:$ZZ$76,RESULTS!$I$3:$ZZ$74),3)) | E6: =IF(B6="","",COUNTIF(_xlfn.XLOOKUP(B6,RESULTS!$I$76:$ZZ$76,RESULTS!$I$3:$ZZ$74),1))
D7: =IF(B7="","",COUNTIF(_xlfn.XLOOKUP(B7,RESULTS!$I$76:$ZZ$76,RESULTS!$I$3:$ZZ$74),3)) | E7: =IF(B7="","",COUNTIF(_xlfn.XLOOKUP(B7,RESULTS!$I$76:$ZZ$76,RESULTS!$I$3:$ZZ$74),1))
D8: =IF(B8="","",COUNTIF(_xlfn.XLOOKUP(B8,RESULTS!$I$76:$ZZ$76,RESULTS!$I$3:$ZZ$74),3)) | E8: =IF(B8="","",COUNTIF(_xlfn.XLOOKUP(B8,RESULTS!$I$76:$ZZ$76,RESULTS!$I$3:$ZZ$74),1))
D9: =IF(B9="","",COUNTIF(_xlfn.XLOOKUP(B9,RESULTS!$I$76:$ZZ$76,RESULTS!$I$3:$ZZ$74),3)) | E9: =IF(B9="","",COUNTIF(_xlfn.XLOOKUP(B9,RESULTS!$I$76:$ZZ$76,RESULTS!$I$3:$ZZ$74),1))
D10: =IF(B10="","",COUNTIF(_xlfn.XLOOKUP(B10,RESULTS!$I$76:$ZZ$76,RESULTS!$I$3:$ZZ$74),3)) | E10: =IF(B10="","",COUNTIF(_xlfn.XLOOKUP(B10,RESULTS!$I$76:$ZZ$76,RESULTS!$I$3:$ZZ$74),1))
D11: =IF(B11="","",COUNTIF(_xlfn.XLOOKUP(B11,RESULTS!$I$76:$ZZ$76,RESULTS!$I$3:$ZZ$74),3)) | E11: =IF(B11="","",COUNTIF(_xlfn.XLOOKUP(B11,RESULTS!$I$76:$ZZ$76,RESULTS!$I$3:$ZZ$74),1))
D12: =IF(B12="","",COUNTIF(_xlfn.XLOOKUP(B12,RESULTS!$I$76:$ZZ$76,RESULTS!$I$3:$ZZ$74),3)) | E12: =IF(B12="","",COUNTIF(_xlfn.XLOOKUP(B12,RESULTS!$I$76:$ZZ$76,RESULTS!$I$3:$ZZ$74),1))
D13: =IF(B13="","",COUNTIF(_xlfn.XLOOKUP(B13,RESULTS!$I$76:$ZZ$76,RESULTS!$I$3:$ZZ$74),3)) | E13: =IF(B13="","",COUNTIF(_xlfn.XLOOKUP(B13,RESULTS!$I$76:$ZZ$76,RESULTS!$I$3:$ZZ$74),1))
D14: =IF(B14="","",COUNTIF(_xlfn.XLOOKUP(B14,RESULTS!$I$76:$ZZ$76,RESULTS!$I$3:$ZZ$74),3)) | E14: =IF(B14="","",COUNTIF(_xlfn.XLOOKUP(B14,RESULTS!$I$76:$ZZ$76,RESULTS!$I$3:$ZZ$74),1))
... D150: =IF(B150="","",COUNTIF(_xlfn.XLOOKUP(B150,RESULTS!$I$76:$ZZ$76,RESULTS!$I$3:$ZZ$74),3)) | E150: =IF(B150="","",COUNTIF(_xlfn.XLOOKUP(B150,RESULTS!$I$76:$ZZ$76,RESULTS!$I$3:$ZZ$74),1))
D151: =IF(B151="","",COUNTIF(_xlfn.XLOOKUP(B151,RESULTS!$I$76:$ZZ$76,RESULTS!$I$3:$ZZ$74),3))
D152: =IF(B152="","",COUNTIF(_xlfn.XLOOKUP(B152,RESULTS!$I$76:$ZZ$76,RESULTS!$I$3:$ZZ$74),3))
D153: =IF(B153="","",COUNTIF(_xlfn.XLOOKUP(B153,RESULTS!$I$76:$ZZ$76,RESULTS!$I$3:$ZZ$74),3))
D154: =IF(B154="","",COUNTIF(_xlfn.XLOOKUP(B154,RESULTS!$I$76:$ZZ$76,RESULTS!$I$3:$ZZ$74),3))
D155: =IF(B155="","",COUNTIF(_xlfn.XLOOKUP(B155,RESULTS!$I$76:$ZZ$76,RESULTS!$I$3:$ZZ$74),3))
D156: =IF(B156="","",COUNTIF(_xlfn.XLOOKUP(B156,RESULTS!$I$76:$ZZ$76,RESULTS!$I$3:$ZZ$74),3))
D157: =IF(B157="","",COUNTIF(_xlfn.XLOOKUP(B157,RESULTS!$I$76:$ZZ$76,RESULTS!$I$3:$ZZ$74),3))
D158: =IF(B158="","",COUNTIF(_xlfn.XLOOKUP(B158,RESULTS!$I$76:$ZZ$76,RESULTS!$I$3:$ZZ$74),3))
D159: =IF(B159="","",COUNTIF(_xlfn.XLOOKUP(B159,RESULTS!$I$76:$ZZ$76,RESULTS!$I$3:$ZZ$74),3))
D160: =IF(B160="","",COUNTIF(_xlfn.XLOOKUP(B160,RESULTS!$I$76:$ZZ$76,RESULTS!$I$3:$ZZ$74),3))
D161: =IF(B161="","",COUNTIF(_xlfn.XLOOKUP(B161,RESULTS!$I$76:$ZZ$76,RESULTS!$I$3:$ZZ$74),3))
D162: =IF(B162="","",COUNTIF(_xlfn.XLOOKUP(B162,RESULTS!$I$76:$ZZ$76,RESULTS!$I$3:$ZZ$74),3))
... D169: =IF(B169="","",COUNTIF(_xlfn.XLOOKUP(B169,RESULTS!$I$76:$ZZ$76,RESULTS!$I$3:$ZZ$74),3))

Sheet RESULTS
A1: =COUNTA($F$1:$JA$1) -> 85 | B1: PLAYERS | G1: Name | J1: Name | M1: Name | P1: Name | S1: Name | V1: Name | Y1: Name | AB1: Name | AE1: Name | AH1: Name | AK1: Name | AN1: Name | AQ1: Name | AT1: Name | AW1: Name | AZ1: Name | BC1: Name | BF1: Name | BI1: Name | BL1: Name | BO1: Name | BR1: Name | BU1: Name | BX1: Name | CA1: Name | CD1: Name | CG1: Name | CJ1: Name | CM1: Name | CP1: Name | CS1: Name | CV1: Name | CY1: Name | DB1: Name | DE1: Name | DH1: Name | DK1: Name | DN1: Name | DQ1: Name | DT1: Name | DW1: Name | DZ1: Name | EC1: Name | EF1: Name | EI1: Name | EL1: Name | EO1: Name | ER1: Name | EU1: Name | EX1: Name | FA1: Name | FD1: Name | FG1: Name | FJ1: Name | FM1: Name | FP1: Name | FS1: Name | FV1: Name | FY1: Name | GB1: Name | GE1: Name | GH1: Name | GK1: Name | GN1: Name | GQ1: Name | GT1: Name | GW1: Name | GZ1: Name | HC1: Name | HF1: Name | HI1: Name | HL1: Name | HO1: Name | HR1: Name | HU1: Name | HX1: Name | IA1: Name | ID1: Name | IG1: Name | IJ1: Name | IM1: Name | IP1: Name | IS1: Name | IV1: Name | IY1: Name | JB1: Name
A2: Date | B2: Team 1 | C2: SCORE | E2: Team 2 | G2: PRED. | I2: Pts | J2: PRED. | L2: Pts | M2: PRED. | O2: Pts | P2: PRED. | R2: Pts | S2: PRED. | U2: Pts | V2: PRED. | X2: Pts | Y2: PRED. | AA2: Pts | AB2: PRED. | AD2: Pts | AE2: PRED. | AG2: Pts | AH2: PRED. | AJ2: Pts | AK2: PRED. | AM2: Pts | AN2: PRED. | AP2: Pts | AQ2: PRED. | AS2: Pts | AT2: PRED. | AV2: Pts | AW2: PRED. | AY2: Pts | AZ2: PRED. | BB2: Pts | BC2: PRED. | BE2: Pts | BF2: PRED. | BH2: Pts | BI2: PRED. | BK2: Pts | BL2: PRED. | BN2: Pts | BO2: PRED. | BQ2: Pts | BR2: PRED. | BT2: Pts | BU2: PRED. | BW2: Pts | BX2: PRED. | BZ2: Pts | CA2: PRED. | CC2: Pts | CD2: PRED. | CF2: Pts | CG2: PRED. | CI2: Pts | CJ2: PRED. | CL2: Pts | CM2: PRED. | CO2: Pts | CP2: PRED. | CR2: Pts | CS2: PRED. | CU2: Pts | CV2: PRED. | CX2: Pts | CY2: PRED. | DA2: Pts | DB2: PRED. | DD2: Pts | DE2: PRED. | DG2: Pts | DH2: PRED. | DJ2: Pts | DK2: PRED. | DM2: Pts | DN2: PRED. | DP2: Pts | DQ2: PRED. | DS2: Pts | DT2: PRED. | DV2: Pts | DW2: PRED. | DY2: Pts | DZ2: PRED. | EB2: Pts | EC2: PRED. | EE2: Pts | EF2: PRED. | EH2: Pts | EI2: PRED. | EK2: Pts | EL2: PRED. | EN2: Pts | EO2: PRED. | EQ2: Pts | ER2: PRED. | ET2: Pts | EU2: PRED. | EW2: Pts | EX2: PRED. | EZ2: Pts | FA2: PRED. | FC2: Pts | FD2: PRED. | FF2: Pts | FG2: PRED. | FI2: Pts | FJ2: PRED. | FL2: Pts | FM2: PRED. | FO2: Pts | FP2: PRED. | FR2: Pts | FS2: PRED. | FU2: Pts | FV2: PRED. | FX2: Pts | FY2: PRED. | GA2: Pts | GB2: PRED. | GD2: Pts | GE2: PRED. | GG2: Pts | GH2: PRED. | GJ2: Pts | GK2: PRED. | GM2: Pts | GN2: PRED. | GP2: Pts | GQ2: PRED. | GS2: Pts | GT2: PRED. | GV2: Pts | GW2: PRED. | GY2: Pts | GZ2: PRED. | HB2: Pts | HC2: PRED. | HE2: Pts | HF2: PRED. | HH2: Pts | HI2: PRED. | HK2: Pts | HL2: PRED. | HN2: Pts | HO2: PRED. | HQ2: Pts | HR2: PRED. | HT2: Pts | HU2: PRED. | HW2: Pts | HX2: PRED. | HZ2: Pts | IA2: PRED. | IC2: Pts | ID2: PRED. | IF2: Pts | IG2: PRED. | II2: Pts | IJ2: PRED. | IL2: Pts | IM2: PRED. | IO2: Pts | IP2: PRED. | IR2: Pts | IS2: PRED. | IU2: Pts | IV2: PRED. | IX2: Pts | IY2: PRED. | JA2: Pts | JB2: PRED. | JD2: Pts
A3: 46184 | B3: Mexico | C3: {=_xlfn.LET( _xlpm.x,_xlfn.XLOOKUP(1,(Scores_Fixtures[Date]=A3)*(Scores_Fixtures[Home.1]=B3),Scores_Fixtures[Score.1],""), IF(_xlpm.x="","",_xlpm.x) )} | D3: {=_xlfn.LET( _xlpm.x,_xlfn.XLOOKUP(1,(Scores_Fixtures[Date]=A3)*(Scores_Fixtures[Home.1]=B3),Scores_Fixtures[Score.2],""), IF(_xlpm.x="","",_xlpm.x) )} | E3: South Africa | I3: {=_xlfn.IFS($D3="","",AND(G3=$C3,H3=$D3),3,($C3-$D3)/MAX(ABS($C3-$D3),1)=(G3-H3)/MAX(ABS(G3-H3),1),1,TRUE,0)} | L3: {=_xlfn.IFS($D3="","",AND(J3=$C3,K3=$D3),3,($C3-$D3)/MAX(ABS($C3-$D3),1)=(J3-K3)/MAX(ABS(J3-K3),1),1,TRUE,0)} | O3: {=_xlfn.IFS($D3="","",AND(M3=$C3,N3=$D3),3,($C3-$D3)/MAX(ABS($C3-$D3),1)=(M3-N3)/MAX(ABS(M3-N3),1),1,TRUE,0)} | R3: {=_xlfn.IFS($D3="","",AND(P3=$C3,Q3=$D3),3,($C3-$D3)/MAX(ABS($C3-$D3),1)=(P3-Q3)/MAX(ABS(P3-Q3),1),1,TRUE,0)} | U3: {=_xlfn.IFS($D3="","",AND(S3=$C3,T3=$D3),3,($C3-$D3)/MAX(ABS($C3-$D3),1)=(S3-T3)/MAX(ABS(S3-T3),1),1,TRUE,0)} | X3: {=_xlfn.IFS($D3="","",AND(V3=$C3,W3=$D3),3,($C3-$D3)/MAX(ABS($C3-$D3),1)=(V3-W3)/MAX(ABS(V3-W3),1),1,TRUE,0)} | AA3: {=_xlfn.IFS($D3="","",AND(Y3=$C3,Z3=$D3),3,($C3-$D3)/MAX(ABS($C3-$D3),1)=(Y3-Z3)/MAX(ABS(Y3-Z3),1),1,TRUE,0)} | AD3: {=_xlfn.IFS($D3="","",AND(AB3=$C3,AC3=$D3),3,($C3-$D3)/MAX(ABS($C3-$D3),1)=(AB3-AC3)/MAX(ABS(AB3-AC3),1),1,TRUE,0)} | AG3: {=_xlfn.IFS($D3="","",AND(AE3=$C3,AF3=$D3),3,($C3-$D3)/MAX(ABS($C3-$D3),1)=(AE3-AF3)/MAX(ABS(AE3-AF3),1),1,TRUE,0)} | AJ3: {=_xlfn.IFS($D3="","",AND(AH3=$C3,AI3=$D3),3,($C3-$D3)/MAX(ABS($C3-$D3),1)=(AH3-AI3)/MAX(ABS(AH3-AI3),1),1,TRUE,0)} | AM3: {=_xlfn.IFS($D3="","",AND(AK3=$C3,AL3=$D3),3,($C3-$D3)/MAX(ABS($C3-$D3),1)=(AK3-AL3)/MAX(ABS(AK3-AL3),1),1,TRUE,0)} | AP3: {=_xlfn.IFS($D3="","",AND(AN3=$C3,AO3=$D3),3,($C3-$D3)/MAX(ABS($C3-$D3),1)=(AN3-AO3)/MAX(ABS(AN3-AO3),1),1,TRUE,0)} | AS3: {=_xlfn.IFS($D3="","",AND(AQ3=$C3,AR3=$D3),3,($C3-$D3)/MAX(ABS($C3-$D3),1)=(AQ3-AR3)/MAX(ABS(AQ3-AR3),1),1,TRUE,0)} | AV3: {=_xlfn.IFS($D3="","",AND(AT3=$C3,AU3=$D3),3,($C3-$D3)/MAX(ABS($C3-$D3),1)=(AT3-AU3)/MAX(ABS(AT3-AU3),1),1,TRUE,0)} | AY3: {=_xlfn.IFS($D3="","",AND(AW3=$C3,AX3=$D3),3,($C3-$D3)/MAX(ABS($C3-$D3),1)=(AW3-AX3)/MAX(ABS(AW3-AX3),1),1,TRUE,0)} | BB3: {=_xlfn.IFS($D3="","",AND(AZ3=$C3,BA3=$D3),3,($C3-$D3)/MAX(ABS($C3-$D3),1)=(AZ3-BA3)/MAX(ABS(AZ3-BA3),1),1,TRUE,0)} | BE3: {=_xlfn.IFS($D3="","",AND(BC3=$C3,BD3=$D3),3,($C3-$D3)/MAX(ABS($C3-$D3),1)=(BC3-BD3)/MAX(ABS(BC3-BD3),1),1,TRUE,0)} | BH3: {=_xlfn.IFS($D3="","",AND(BF3=$C3,BG3=$D3),3,($C3-$D3)/MAX(ABS($C3-$D3),1)=(BF3-BG3)/MAX(ABS(BF3-BG3),1),1,TRUE,0)} | BK3: {=_xlfn.IFS($D3="","",AND(BI3=$C3,BJ3=$D3),3,($C3-$D3)/MAX(ABS($C3-$D3),1)=(BI3-BJ3)/MAX(ABS(BI3-BJ3),1),1,TRUE,0)} | BN3: {=_xlfn.IFS($D3="","",AND(BL3=$C3,BM3=$D3),3,($C3-$D3)/MAX(ABS($C3-$D3),1)=(BL3-BM3)/MAX(ABS(BL3-BM3),1),1,TRUE,0)} | BQ3: {=_xlfn.IFS($D3="","",AND(BO3=$C3,BP3=$D3),3,($C3-$D3)/MAX(ABS($C3-$D3),1)=(BO3-BP3)/MAX(ABS(BO3-BP3),1),1,TRUE,0)} | BT3: {=_xlfn.IFS($D3="","",AND(BR3=$C3,BS3=$D3),3,($C3-$D3)/MAX(ABS($C3-$D3),1)=(BR3-BS3)/MAX(ABS(BR3-BS3),1),1,TRUE,0)} | BW3: {=_xlfn.IFS($D3="","",AND(BU3=$C3,BV3=$D3),3,($C3-$D3)/MAX(ABS($C3-$D3),1)=(BU3-BV3)/MAX(ABS(BU3-BV3),1),1,TRUE,0)} | BZ3: {=_xlfn.IFS($D3="","",AND(BX3=$C3,BY3=$D3),3,($C3-$D3)/MAX(ABS($C3-$D3),1)=(BX3-BY3)/MAX(ABS(BX3-BY3),1),1,TRUE,0)} | CC3: {=_xlfn.IFS($D3="","",AND(CA3=$C3,CB3=$D3),3,($C3-$D3)/MAX(ABS($C3-$D3),1)=(CA3-CB3)/MAX(ABS(CA3-CB3),1),1,TRUE,0)} | CF3: {=_xlfn.IFS($D3="","",AND(CD3=$C3,CE3=$D3),3,($C3-$D3)/MAX(ABS($C3-$D3),1)=(CD3-CE3)/MAX(ABS(CD3-CE3),1),1,TRUE,0)} | CI3: {=_xlfn.IFS($D3="","",AND(CG3=$C3,CH3=$D3),3,($C3-$D3)/MAX(ABS($C3-$D3),1)=(CG3-CH3)/MAX(ABS(CG3-CH3),1),1,TRUE,0)} | CL3: {=_xlfn.IFS($D3="","",AND(CJ3=$C3,CK3=$D3),3,($C3-$D3)/MAX(ABS($C3-$D3),1)=(CJ3-CK3)/MAX(ABS(CJ3-CK3),1),1,TRUE,0)} | CO3: {=_xlfn.IFS($D3="","",AND(CM3=$C3,CN3=$D3),3,($C3-$D3)/MAX(ABS($C3-$D3),1)=(CM3-CN3)/MAX(ABS(CM3-CN3),1),1,TRUE,0)} | CR3: {=_xlfn.IFS($D3="","",AND(CP3=$C3,CQ3=$D3),3,($C3-$D3)/MAX(ABS($C3-$D3),1)=(CP3-CQ3)/MAX(ABS(CP3-CQ3),1),1,TRUE,0)} | CU3: {=_xlfn.IFS($D3="","",AND(CS3=$C3,CT3=$D3),3,($C3-$D3)/MAX(ABS($C3-$D3),1)=(CS3-CT3)/MAX(ABS(CS3-CT3),1),1,TRUE,0)} | CX3: {=_xlfn.IFS($D3="","",AND(CV3=$C3,CW3=$D3),3,($C3-$D3)/MAX(ABS($C3-$D3),1)=(CV3-CW3)/MAX(ABS(CV3-CW3),1),1,TRUE,0)} | DA3: {=_xlfn.IFS($D3="","",AND(CY3=$C3,CZ3=$D3),3,($C3-$D3)/MAX(ABS($C3-$D3),1)=(CY3-CZ3)/MAX(ABS(CY3-CZ3),1),1,TRUE,0)} | DD3: {=_xlfn.IFS($D3="","",AND(DB3=$C3,DC3=$D3),3,($C3-$D3)/MAX(ABS($C3-$D3),1)=(DB3-DC3)/MAX(ABS(DB3-DC3),1),1,TRUE,0)} | DG3: {=_xlfn.IFS($D3="","",AND(DE3=$C3,DF3=$D3),3,($C3-$D3)/MAX(ABS($C3-$D3),1)=(DE3-DF3)/MAX(ABS(DE3-DF3),1),1,TRUE,0)} | DJ3: {=_xlfn.IFS($D3="","",AND(DH3=$C3,DI3=$D3),3,($C3-$D3)/MAX(ABS($C3-$D3),1)=(DH3-DI3)/MAX(ABS(DH3-DI3),1),1,TRUE,0)} | DM3: {=_xlfn.IFS($D3="","",AND(DK3=$C3,DL3=$D3),3,($C3-$D3)/MAX(ABS($C3-$D3),1)=(DK3-DL3)/MAX(ABS(DK3-DL3),1),1,TRUE,0)} | DP3: {=_xlfn.IFS($D3="","",AND(DN3=$C3,DO3=$D3),3,($C3-$D3)/MAX(ABS($C3-$D3),1)=(DN3-DO3)/MAX(ABS(DN3-DO3),1),1,TRUE,0)} | DS3: {=_xlfn.IFS($D3="","",AND(DQ3=$C3,DR3=$D3),3,($C3-$D3)/MAX(ABS($C3-$D3),1)=(DQ3-DR3)/MAX(ABS(DQ3-DR3),1),1,TRUE,0)} | DV3: {=_xlfn.IFS($D3="","",AND(DT3=$C3,DU3=$D3),3,($C3-$D3)/MAX(ABS($C3-$D3),1)=(DT3-DU3)/MAX(ABS(DT3-DU3),1),1,TRUE,0)} | DY3: {=_xlfn.IFS($D3="","",AND(DW3=$C3,DX3=$D3),3,($C3-$D3)/MAX(ABS($C3-$D3),1)=(DW3-DX3)/MAX(ABS(DW3-DX3),1),1,TRUE,0)} | EB3: {=_xlfn.IFS($D3="","",AND(DZ3=$C3,EA3=$D3),3,($C3-$D3)/MAX(ABS($C3-$D3),1)=(DZ3-EA3)/MAX(ABS(DZ3-EA3),1),1,TRUE,0)} | EE3: {=_xlfn.IFS($D3="","",AND(EC3=$C3,ED3=$D3),3,($C3-$D3)/MAX(ABS($C3-$D3),1)=(EC3-ED3)/MAX(ABS(EC3-ED3),1),1,TRUE,0)} | EH3: {=_xlfn.IFS($D3="","",AND(EF3=$C3,EG3=$D3),3,($C3-$D3)/MAX(ABS($C3-$D3),1)=(EF3-EG3)/MAX(ABS(EF3-EG3),1),1,TRUE,0)} | EK3: {=_xlfn.IFS($D3="","",AND(EI3=$C3,EJ3=$D3),3,($C3-$D3)/MAX(ABS($C3-$D3),1)=(EI3-EJ3)/MAX(ABS(EI3-EJ3),1),1,TRUE,0)} | EN3: {=_xlfn.IFS($D3="","",AND(EL3=$C3,EM3=$D3),3,($C3-$D3)/MAX(ABS($C3-$D3),1)=(EL3-EM3)/MAX(ABS(EL3-EM3),1),1,TRUE,0)} | EQ3: {=_xlfn.IFS($D3="","",AND(EO3=$C3,EP3=$D3),3,($C3-$D3)/MAX(ABS($C3-$D3),1)=(EO3-EP3)/MAX(ABS(EO3-EP3),1),1,TRUE,0)} | ET3: {=_xlfn.IFS($D3="","",AND(ER3=$C3,ES3=$D3),3,($C3-$D3)/MAX(ABS($C3-$D3),1)=(ER3-ES3)/MAX(ABS(ER3-ES3),1),1,TRUE,0)} | EW3: {=_xlfn.IFS($D3="","",AND(EU3=$C3,EV3=$D3),3,($C3-$D3)/MAX(ABS($C3-$D3),1)=(EU3-EV3)/MAX(ABS(EU3-EV3),1),1,TRUE,0)} | EZ3: {=_xlfn.IFS($D3="","",AND(EX3=$C3,EY3=$D3),3,($C3-$D3)/MAX(ABS($C3-$D3),1)=(EX3-EY3)/MAX(ABS(EX3-EY3),1),1,TRUE,0)} | FC3: {=_xlfn.IFS($D3="","",AND(FA3=$C3,FB3=$D3),3,($C3-$D3)/MAX(ABS($C3-$D3),1)=(FA3-FB3)/MAX(ABS(FA3-FB3),1),1,TRUE,0)} | FF3: {=_xlfn.IFS($D3="","",AND(FD3=$C3,FE3=$D3),3,($C3-$D3)/MAX(ABS($C3-$D3),1)=(FD3-FE3)/MAX(ABS(FD3-FE3),1),1,TRUE,0)} | FI3: {=_xlfn.IFS($D3="","",AND(FG3=$C3,FH3=$D3),3,($C3-$D3)/MAX(ABS($C3-$D3),1)=(FG3-FH3)/MAX(ABS(FG3-FH3),1),1,TRUE,0)} | FL3: {=_xlfn.IFS($D3="","",AND(FJ3=$C3,FK3=$D3),3,($C3-$D3)/MAX(ABS($C3-$D3),1)=(FJ3-FK3)/MAX(ABS(FJ3-FK3),1),1,TRUE,0)} | FO3: {=_xlfn.IFS($D3="","",AND(FM3=$C3,FN3=$D3),3,($C3-$D3)/MAX(ABS($C3-$D3),1)=(FM3-FN3)/MAX(ABS(FM3-FN3),1),1,TRUE,0)} | FR3: {=_xlfn.IFS($D3="","",AND(FP3=$C3,FQ3=$D3),3,($C3-$D3)/MAX(ABS($C3-$D3),1)=(FP3-FQ3)/MAX(ABS(FP3-FQ3),1),1,TRUE,0)} | FU3: {=_xlfn.IFS($D3="","",AND(FS3=$C3,FT3=$D3),3,($C3-$D3)/MAX(ABS($C3-$D3),1)=(FS3-FT3)/MAX(ABS(FS3-FT3),1),1,TRUE,0)} | FX3: {=_xlfn.IFS($D3="","",AND(FV3=$C3,FW3=$D3),3,($C3-$D3)/MAX(ABS($C3-$D3),1)=(FV3-FW3)/MAX(ABS(FV3-FW3),1),1,TRUE,0)} | GA3: {=_xlfn.IFS($D3="","",AND(FY3=$C3,FZ3=$D3),3,($C3-$D3)/MAX(ABS($C3-$D3),1)=(FY3-FZ3)/MAX(ABS(FY3-FZ3),1),1,TRUE,0)} | GD3: {=_xlfn.IFS($D3="","",AND(GB3=$C3,GC3=$D3),3,($C3-$D3)/MAX(ABS($C3-$D3),1)=(GB3-GC3)/MAX(ABS(GB3-GC3),1),1,TRUE,0)} | GG3: {=_xlfn.IFS($D3="","",AND(GE3=$C3,GF3=$D3),3,($C3-$D3)/MAX(ABS($C3-$D3),1)=(GE3-GF3)/MAX(ABS(GE3-GF3),1),1,TRUE,0)} | GJ3: {=_xlfn.IFS($D3="","",AND(GH3=$C3,GI3=$D3),3,($C3-$D3)/MAX(ABS($C3-$D3),1)=(GH3-GI3)/MAX(ABS(GH3-GI3),1),1,TRUE,0)} | GM3: {=_xlfn.IFS($D3="","",AND(GK3=$C3,GL3=$D3),3,($C3-$D3)/MAX(ABS($C3-$D3),1)=(GK3-GL3)/MAX(ABS(GK3-GL3),1),1,TRUE,0)} | GP3: {=_xlfn.IFS($D3="","",AND(GN3=$C3,GO3=$D3),3,($C3-$D3)/MAX(ABS($C3-$D3),1)=(GN3-GO3)/MAX(ABS(GN3-GO3),1),1,TRUE,0)} | GS3: {=_xlfn.IFS($D3="","",AND(GQ3=$C3,GR3=$D3),3,($C3-$D3)/MAX(ABS($C3-$D3),1)=(GQ3-GR3)/MAX(ABS(GQ3-GR3),1),1,TRUE,0)} | GV3: {=_xlfn.IFS($D3="","",AND(GT3=$C3,GU3=$D3),3,($C3-$D3)/MAX(ABS($C3-$D3),1)=(GT3-GU3)/MAX(ABS(GT3-GU3),1),1,TRUE,0)} | GY3: {=_xlfn.IFS($D3="","",AND(GW3=$C3,GX3=$D3),3,($C3-$D3)/MAX(ABS($C3-$D3),1)=(GW3-GX3)/MAX(ABS(GW3-GX3),1),1,TRUE,0)} | HB3: {=_xlfn.IFS($D3="","",AND(GZ3=$C3,HA3=$D3),3,($C3-$D3)/MAX(ABS($C3-$D3),1)=(GZ3-HA3)/MAX(ABS(GZ3-HA3),1),1,TRUE,0)} | HE3: {=_xlfn.IFS($D3="","",AND(HC3=$C3,HD3=$D3),3,($C3-$D3)/MAX(ABS($C3-$D3),1)=(HC3-HD3)/MAX(ABS(HC3-HD3),1),1,TRUE,0)} | HH3: {=_xlfn.IFS($D3="","",AND(HF3=$C3,HG3=$D3),3,($C3-$D3)/MAX(ABS($C3-$D3),1)=(HF3-HG3)/MAX(ABS(HF3-HG3),1),1,TRUE,0)} | HK3: {=_xlfn.IFS($D3="","",AND(HI3=$C3,HJ3=$D3),3,($C3-$D3)/MAX(ABS($C3-$D3),1)=(HI3-HJ3)/MAX(ABS(HI3-HJ3),1),1,TRUE,0)} | HN3: {=_xlfn.IFS($D3="","",AND(HL3=$C3,HM3=$D3),3,($C3-$D3)/MAX(ABS($C3-$D3),1)=(HL3-HM3)/MAX(ABS(HL3-HM3),1),1,TRUE,0)} | HQ3: {=_xlfn.IFS($D3="","",AND(HO3=$C3,HP3=$D3),3,($C3-$D3)/MAX(ABS($C3-$D3),1)=(HO3-HP3)/MAX(ABS(HO3-HP3),1),1,TRUE,0)} | HT3: {=_xlfn.IFS($D3="","",AND(HR3=$C3,HS3=$D3),3,($C3-$D3)/MAX(ABS($C3-$D3),1)=(HR3-HS3)/MAX(ABS(HR3-HS3),1),1,TRUE,0)} | HW3: {=_xlfn.IFS($D3="","",AND(HU3=$C3,HV3=$D3),3,($C3-$D3)/MAX(ABS($C3-$D3),1)=(HU3-HV3)/MAX(ABS(HU3-HV3),1),1,TRUE,0)} | HZ3: {=_xlfn.IFS($D3="","",AND(HX3=$C3,HY3=$D3),3,($C3-$D3)/MAX(ABS($C3-$D3),1)=(HX3-HY3)/MAX(ABS(HX3-HY3),1),1,TRUE,0)} | IC3: {=_xlfn.IFS($D3="","",AND(IA3=$C3,IB3=$D3),3,($C3-$D3)/MAX(ABS($C3-$D3),1)=(IA3-IB3)/MAX(ABS(IA3-IB3),1),1,TRUE,0)} | IF3: {=_xlfn.IFS($D3="","",AND(ID3=$C3,IE3=$D3),3,($C3-$D3)/MAX(ABS($C3-$D3),1)=(ID3-IE3)/MAX(ABS(ID3-IE3),1),1,TRUE,0)} | II3: {=_xlfn.IFS($D3="","",AND(IG3=$C3,IH3=$D3),3,($C3-$D3)/MAX(ABS($C3-$D3),1)=(IG3-IH3)/MAX(ABS(IG3-IH3),1),1,TRUE,0)} | IL3: {=_xlfn.IFS($D3="","",AND(IJ3=$C3,IK3=$D3),3,($C3-$D3)/MAX(ABS($C3-$D3),1)=(IJ3-IK3)/MAX(ABS(IJ3-IK3),1),1,TRUE,0)} | IO3: {=_xlfn.IFS($D3="","",AND(IM3=$C3,IN3=$D3),3,($C3-$D3)/MAX(ABS($C3-$D3),1)=(IM3-IN3)/MAX(ABS(IM3-IN3),1),1,TRUE,0)} | IR3: {=_xlfn.IFS($D3="","",AND(IP3=$C3,IQ3=$D3),3,($C3-$D3)/MAX(ABS($C3-$D3),1)=(IP3-IQ3)/MAX(ABS(IP3-IQ3),1),1,TRUE,0)} | IU3: {=_xlfn.IFS($D3="","",AND(IS3=$C3,IT3=$D3),3,($C3-$D3)/MAX(ABS($C3-$D3),1)=(IS3-IT3)/MAX(ABS(IS3-IT3),1),1,TRUE,0)} | IX3: {=_xlfn.IFS($D3="","",AND(IV3=$C3,IW3=$D3),3,($C3-$D3)/MAX(ABS($C3-$D3),1)=(IV3-IW3)/MAX(ABS(IV3-IW3),1),1,TRUE,0)} | JA3: {=_xlfn.IFS($D3="","",AND(IY3=$C3,IZ3=$D3),3,($C3-$D3)/MAX(ABS($C3-$D3),1)=(IY3-IZ3)/MAX(ABS(IY3-IZ3),1),1,TRUE,0)} | JD3: {=_xlfn.IFS($D3="","",AND(JB3=$C3,JC3=$D3),3,($C3-$D3)/MAX(ABS($C3-$D3),1)=(JB3-JC3)/MAX(ABS(JB3-JC3),1),1,TRUE,0)}
A4: 46185 | B4: Rep. of Korea | C4: {=_xlfn.LET( _xlpm.x,_xlfn.XLOOKUP(1,(Scores_Fixtures[Date]=A4)*(Scores_Fixtures[Home.1]=B4),Scores_Fixtures[Score.1],""), IF(_xlpm.x="","",_xlpm.x) )} | D4: {=_xlfn.LET( _xlpm.x,_xlfn.XLOOKUP(1,(Scores_Fixtures[Date]=A4)*(Scores_Fixtures[Home.1]=B4),Scores_Fixtures[Score.2],""), IF(_xlpm.x="","",_xlpm.x) )} | E4: Czechia | I4: {=_xlfn.IFS($D4="","",AND(G4=$C4,H4=$D4),3,($C4-$D4)/MAX(ABS($C4-$D4),1)=(G4-H4)/MAX(ABS(G4-H4),1),1,TRUE,0)} | L4: {=_xlfn.IFS($D4="","",AND(J4=$C4,K4=$D4),3,($C4-$D4)/MAX(ABS($C4-$D4),1)=(J4-K4)/MAX(ABS(J4-K4),1),1,TRUE,0)} | O4: {=_xlfn.IFS($D4="","",AND(M4=$C4,N4=$D4),3,($C4-$D4)/MAX(ABS($C4-$D4),1)=(M4-N4)/MAX(ABS(M4-N4),1),1,TRUE,0)} | R4: {=_xlfn.IFS($D4="","",AND(P4=$C4,Q4=$D4),3,($C4-$D4)/MAX(ABS($C4-$D4),1)=(P4-Q4)/MAX(ABS(P4-Q4),1),1,TRUE,0)} | U4: {=_xlfn.IFS($D4="","",AND(S4=$C4,T4=$D4),3,($C4-$D4)/MAX(ABS($C4-$D4),1)=(S4-T4)/MAX(ABS(S4-T4),1),1,TRUE,0)} | X4: {=_xlfn.IFS($D4="","",AND(V4=$C4,W4=$D4),3,($C4-$D4)/MAX(ABS($C4-$D4),1)=(V4-W4)/MAX(ABS(V4-W4),1),1,TRUE,0)} | AA4: {=_xlfn.IFS($D4="","",AND(Y4=$C4,Z4=$D4),3,($C4-$D4)/MAX(ABS($C4-$D4),1)=(Y4-Z4)/MAX(ABS(Y4-Z4),1),1,TRUE,0)} | AD4: {=_xlfn.IFS($D4="","",AND(AB4=$C4,AC4=$D4),3,($C4-$D4)/MAX(ABS($C4-$D4),1)=(AB4-AC4)/MAX(ABS(AB4-AC4),1),1,TRUE,0)} | AG4: {=_xlfn.IFS($D4="","",AND(AE4=$C4,AF4=$D4),3,($C4-$D4)/MAX(ABS($C4-$D4),1)=(AE4-AF4)/MAX(ABS(AE4-AF4),1),1,TRUE,0)} | AJ4: {=_xlfn.IFS($D4="","",AND(AH4=$C4,AI4=$D4),3,($C4-$D4)/MAX(ABS($C4-$D4),1)=(AH4-AI4)/MAX(ABS(AH4-AI4),1),1,TRUE,0)} | AM4: {=_xlfn.IFS($D4="","",AND(AK4=$C4,AL4=$D4),3,($C4-$D4)/MAX(ABS($C4-$D4),1)=(AK4-AL4)/MAX(ABS(AK4-AL4),1),1,TRUE,0)} | AP4: {=_xlfn.IFS($D4="","",AND(AN4=$C4,AO4=$D4),3,($C4-$D4)/MAX(ABS($C4-$D4),1)=(AN4-AO4)/MAX(ABS(AN4-AO4),1),1,TRUE,0)} | AS4: {=_xlfn.IFS($D4="","",AND(AQ4=$C4,AR4=$D4),3,($C4-$D4)/MAX(ABS($C4-$D4),1)=(AQ4-AR4)/MAX(ABS(AQ4-AR4),1),1,TRUE,0)} | AV4: {=_xlfn.IFS($D4="","",AND(AT4=$C4,AU4=$D4),3,($C4-$D4)/MAX(ABS($C4-$D4),1)=(AT4-AU4)/MAX(ABS(AT4-AU4),1),1,TRUE,0)} | AY4: {=_xlfn.IFS($D4="","",AND(AW4=$C4,AX4=$D4),3,($C4-$D4)/MAX(ABS($C4-$D4),1)=(AW4-AX4)/MAX(ABS(AW4-AX4),1),1,TRUE,0)} | BB4: {=_xlfn.IFS($D4="","",AND(AZ4=$C4,BA4=$D4),3,($C4-$D4)/MAX(ABS($C4-$D4),1)=(AZ4-BA4)/MAX(ABS(AZ4-BA4),1),1,TRUE,0)} | BE4: {=_xlfn.IFS($D4="","",AND(BC4=$C4,BD4=$D4),3,($C4-$D4)/MAX(ABS($C4-$D4),1)=(BC4-BD4)/MAX(ABS(BC4-BD4),1),1,TRUE,0)} | BH4: {=_xlfn.IFS($D4="","",AND(BF4=$C4,BG4=$D4),3,($C4-$D4)/MAX(ABS($C4-$D4),1)=(BF4-BG4)/MAX(ABS(BF4-BG4),1),1,TRUE,0)} | BK4: {=_xlfn.IFS($D4="","",AND(BI4=$C4,BJ4=$D4),3,($C4-$D4)/MAX(ABS($C4-$D4),1)=(BI4-BJ4)/MAX(ABS(BI4-BJ4),1),1,TRUE,0)} | BN4: {=_xlfn.IFS($D4="","",AND(BL4=$C4,BM4=$D4),3,($C4-$D4)/MAX(ABS($C4-$D4),1)=(BL4-BM4)/MAX(ABS(BL4-BM4),1),1,TRUE,0)} | BQ4: {=_xlfn.IFS($D4="","",AND(BO4=$C4,BP4=$D4),3,($C4-$D4)/MAX(ABS($C4-$D4),1)=(BO4-BP4)/MAX(ABS(BO4-BP4),1),1,TRUE,0)} | BT4: {=_xlfn.IFS($D4="","",AND(BR4=$C4,BS4=$D4),3,($C4-$D4)/MAX(ABS($C4-$D4),1)=(BR4-BS4)/MAX(ABS(BR4-BS4),1),1,TRUE,0)} | BW4: {=_xlfn.IFS($D4="","",AND(BU4=$C4,BV4=$D4),3,($C4-$D4)/MAX(ABS($C4-$D4),1)=(BU4-BV4)/MAX(ABS(BU4-BV4),1),1,TRUE,0)} | BZ4: {=_xlfn.IFS($D4="","",AND(BX4=$C4,BY4=$D4),3,($C4-$D4)/MAX(ABS($C4-$D4),1)=(BX4-BY4)/MAX(ABS(BX4-BY4),1),1,TRUE,0)} | CC4: {=_xlfn.IFS($D4="","",AND(CA4=$C4,CB4=$D4),3,($C4-$D4)/MAX(ABS($C4-$D4),1)=(CA4-CB4)/MAX(ABS(CA4-CB4),1),1,TRUE,0)} | CF4: {=_xlfn.IFS($D4="","",AND(CD4=$C4,CE4=$D4),3,($C4-$D4)/MAX(ABS($C4-$D4),1)=(CD4-CE4)/MAX(ABS(CD4-CE4),1),1,TRUE,0)} | CI4: {=_xlfn.IFS($D4="","",AND(CG4=$C4,CH4=$D4),3,($C4-$D4)/MAX(ABS($C4-$D4),1)=(CG4-CH4)/MAX(ABS(CG4-CH4),1),1,TRUE,0)} | CL4: {=_xlfn.IFS($D4="","",AND(CJ4=$C4,CK4=$D4),3,($C4-$D4)/MAX(ABS($C4-$D4),1)=(CJ4-CK4)/MAX(ABS(CJ4-CK4),1),1,TRUE,0)} | CO4: {=_xlfn.IFS($D4="","",AND(CM4=$C4,CN4=$D4),3,($C4-$D4)/MAX(ABS($C4-$D4),1)=(CM4-CN4)/MAX(ABS(CM4-CN4),1),1,TRUE,0)} | CR4: {=_xlfn.IFS($D4="","",AND(CP4=$C4,CQ4=$D4),3,($C4-$D4)/MAX(ABS($C4-$D4),1)=(CP4-CQ4)/MAX(ABS(CP4-CQ4),1),1,TRUE,0)} | CU4: {=_xlfn.IFS($D4="","",AND(CS4=$C4,CT4=$D4),3,($C4-$D4)/MAX(ABS($C4-$D4),1)=(CS4-CT4)/MAX(ABS(CS4-CT4),1),1,TRUE,0)} | CX4: {=_xlfn.IFS($D4="","",AND(CV4=$C4,CW4=$D4),3,($C4-$D4)/MAX(ABS($C4-$D4),1)=(CV4-CW4)/MAX(ABS(CV4-CW4),1),1,TRUE,0)} | DA4: {=_xlfn.IFS($D4="","",AND(CY4=$C4,CZ4=$D4),3,($C4-$D4)/MAX(ABS($C4-$D4),1)=(CY4-CZ4)/MAX(ABS(CY4-CZ4),1),1,TRUE,0)} | DD4: {=_xlfn.IFS($D4="","",AND(DB4=$C4,DC4=$D4),3,($C4-$D4)/MAX(ABS($C4-$D4),1)=(DB4-DC4)/MAX(ABS(DB4-DC4),1),1,TRUE,0)} | DG4: {=_xlfn.IFS($D4="","",AND(DE4=$C4,DF4=$D4),3,($C4-$D4)/MAX(ABS($C4-$D4),1)=(DE4-DF4)/MAX(ABS(DE4-DF4),1),1,TRUE,0)} | DJ4: {=_xlfn.IFS($D4="","",AND(DH4=$C4,DI4=$D4),3,($C4-$D4)/MAX(ABS($C4-$D4),1)=(DH4-DI4)/MAX(ABS(DH4-DI4),1),1,TRUE,0)} | DM4: {=_xlfn.IFS($D4="","",AND(DK4=$C4,DL4=$D4),3,($C4-$D4)/MAX(ABS($C4-$D4),1)=(DK4-DL4)/MAX(ABS(DK4-DL4),1),1,TRUE,0)} | DP4: {=_xlfn.IFS($D4="","",AND(DN4=$C4,DO4=$D4),3,($C4-$D4)/MAX(ABS($C4-$D4),1)=(DN4-DO4)/MAX(ABS(DN4-DO4),1),1,TRUE,0)} | DS4: {=_xlfn.IFS($D4="","",AND(DQ4=$C4,DR4=$D4),3,($C4-$D4)/MAX(ABS($C4-$D4),1)=(DQ4-DR4)/MAX(ABS(DQ4-DR4),1),1,TRUE,0)} | DV4: {=_xlfn.IFS($D4="","",AND(DT4=$C4,DU4=$D4),3,($C4-$D4)/MAX(ABS($C4-$D4),1)=(DT4-DU4)/MAX(ABS(DT4-DU4),1),1,TRUE,0)} | DY4: {=_xlfn.IFS($D4="","",AND(DW4=$C4,DX4=$D4),3,($C4-$D4)/MAX(ABS($C4-$D4),1)=(DW4-DX4)/MAX(ABS(DW4-DX4),1),1,TRUE,0)} | EB4: {=_xlfn.IFS($D4="","",AND(DZ4=$C4,EA4=$D4),3,($C4-$D4)/MAX(ABS($C4-$D4),1)=(DZ4-EA4)/MAX(ABS(DZ4-EA4),1),1,TRUE,0)} | EE4: {=_xlfn.IFS($D4="","",AND(EC4=$C4,ED4=$D4),3,($C4-$D4)/MAX(ABS($C4-$D4),1)=(EC4-ED4)/MAX(ABS(EC4-ED4),1),1,TRUE,0)} | EH4: {=_xlfn.IFS($D4="","",AND(EF4=$C4,EG4=$D4),3,($C4-$D4)/MAX(ABS($C4-$D4),1)=(EF4-EG4)/MAX(ABS(EF4-EG4),1),1,TRUE,0)} | EK4: {=_xlfn.IFS($D4="","",AND(EI4=$C4,EJ4=$D4),3,($C4-$D4)/MAX(ABS($C4-$D4),1)=(EI4-EJ4)/MAX(ABS(EI4-EJ4),1),1,TRUE,0)} | EN4: {=_xlfn.IFS($D4="","",AND(EL4=$C4,EM4=$D4),3,($C4-$D4)/MAX(ABS($C4-$D4),1)=(EL4-EM4)/MAX(ABS(EL4-EM4),1),1,TRUE,0)} | EQ4: {=_xlfn.IFS($D4="","",AND(EO4=$C4,EP4=$D4),3,($C4-$D4)/MAX(ABS($C4-$D4),1)=(EO4-EP4)/MAX(ABS(EO4-EP4),1),1,TRUE,0)} | ET4: {=_xlfn.IFS($D4="","",AND(ER4=$C4,ES4=$D4),3,($C4-$D4)/MAX(ABS($C4-$D4),1)=(ER4-ES4)/MAX(ABS(ER4-ES4),1),1,TRUE,0)} | EW4: {=_xlfn.IFS($D4="","",AND(EU4=$C4,EV4=$D4),3,($C4-$D4)/MAX(ABS($C4-$D4),1)=(EU4-EV4)/MAX(ABS(EU4-EV4),1),1,TRUE,0)} | EZ4: {=_xlfn.IFS($D4="","",AND(EX4=$C4,EY4=$D4),3,($C4-$D4)/MAX(ABS($C4-$D4),1)=(EX4-EY4)/MAX(ABS(EX4-EY4),1),1,TRUE,0)} | FC4: {=_xlfn.IFS($D4="","",AND(FA4=$C4,FB4=$D4),3,($C4-$D4)/MAX(ABS($C4-$D4),1)=(FA4-FB4)/MAX(ABS(FA4-FB4),1),1,TRUE,0)} | FF4: {=_xlfn.IFS($D4="","",AND(FD4=$C4,FE4=$D4),3,($C4-$D4)/MAX(ABS($C4-$D4),1)=(FD4-FE4)/MAX(ABS(FD4-FE4),1),1,TRUE,0)} | FI4: {=_xlfn.IFS($D4="","",AND(FG4=$C4,FH4=$D4),3,($C4-$D4)/MAX(ABS($C4-$D4),1)=(FG4-FH4)/MAX(ABS(FG4-FH4),1),1,TRUE,0)} | FL4: {=_xlfn.IFS($D4="","",AND(FJ4=$C4,FK4=$D4),3,($C4-$D4)/MAX(ABS($C4-$D4),1)=(FJ4-FK4)/MAX(ABS(FJ4-FK4),1),1,TRUE,0)} | FO4: {=_xlfn.IFS($D4="","",AND(FM4=$C4,FN4=$D4),3,($C4-$D4)/MAX(ABS($C4-$D4),1)=(FM4-FN4)/MAX(ABS(FM4-FN4),1),1,TRUE,0)} | FR4: {=_xlfn.IFS($D4="","",AND(FP4=$C4,FQ4=$D4),3,($C4-$D4)/MAX(ABS($C4-$D4),1)=(FP4-FQ4)/MAX(ABS(FP4-FQ4),1),1,TRUE,0)} | FU4: {=_xlfn.IFS($D4="","",AND(FS4=$C4,FT4=$D4),3,($C4-$D4)/MAX(ABS($C4-$D4),1)=(FS4-FT4)/MAX(ABS(FS4-FT4),1),1,TRUE,0)} | FX4: {=_xlfn.IFS($D4="","",AND(FV4=$C4,FW4=$D4),3,($C4-$D4)/MAX(ABS($C4-$D4),1)=(FV4-FW4)/MAX(ABS(FV4-FW4),1),1,TRUE,0)} | GA4: {=_xlfn.IFS($D4="","",AND(FY4=$C4,FZ4=$D4),3,($C4-$D4)/MAX(ABS($C4-$D4),1)=(FY4-FZ4)/MAX(ABS(FY4-FZ4),1),1,TRUE,0)} | GD4: {=_xlfn.IFS($D4="","",AND(GB4=$C4,GC4=$D4),3,($C4-$D4)/MAX(ABS($C4-$D4),1)=(GB4-GC4)/MAX(ABS(GB4-GC4),1),1,TRUE,0)} | GG4: {=_xlfn.IFS($D4="","",AND(GE4=$C4,GF4=$D4),3,($C4-$D4)/MAX(ABS($C4-$D4),1)=(GE4-GF4)/MAX(ABS(GE4-GF4),1),1,TRUE,0)} | GJ4: {=_xlfn.IFS($D4="","",AND(GH4=$C4,GI4=$D4),3,($C4-$D4)/MAX(ABS($C4-$D4),1)=(GH4-GI4)/MAX(ABS(GH4-GI4),1),1,TRUE,0)} | GM4: {=_xlfn.IFS($D4="","",AND(GK4=$C4,GL4=$D4),3,($C4-$D4)/MAX(ABS($C4-$D4),1)=(GK4-GL4)/MAX(ABS(GK4-GL4),1),1,TRUE,0)} | GP4: {=_xlfn.IFS($D4="","",AND(GN4=$C4,GO4=$D4),3,($C4-$D4)/MAX(ABS($C4-$D4),1)=(GN4-GO4)/MAX(ABS(GN4-GO4),1),1,TRUE,0)} | GS4: {=_xlfn.IFS($D4="","",AND(GQ4=$C4,GR4=$D4),3,($C4-$D4)/MAX(ABS($C4-$D4),1)=(GQ4-GR4)/MAX(ABS(GQ4-GR4),1),1,TRUE,0)} | GV4: {=_xlfn.IFS($D4="","",AND(GT4=$C4,GU4=$D4),3,($C4-$D4)/MAX(ABS($C4-$D4),1)=(GT4-GU4)/MAX(ABS(GT4-GU4),1),1,TRUE,0)} | GY4: {=_xlfn.IFS($D4="","",AND(GW4=$C4,GX4=$D4),3,($C4-$D4)/MAX(ABS($C4-$D4),1)=(GW4-GX4)/MAX(ABS(GW4-GX4),1),1,TRUE,0)} | HB4: {=_xlfn.IFS($D4="","",AND(GZ4=$C4,HA4=$D4),3,($C4-$D4)/MAX(ABS($C4-$D4),1)=(GZ4-HA4)/MAX(ABS(GZ4-HA4),1),1,TRUE,0)} | HE4: {=_xlfn.IFS($D4="","",AND(HC4=$C4,HD4=$D4),3,($C4-$D4)/MAX(ABS($C4-$D4),1)=(HC4-HD4)/MAX(ABS(HC4-HD4),1),1,TRUE,0)} | HH4: {=_xlfn.IFS($D4="","",AND(HF4=$C4,HG4=$D4),3,($C4-$D4)/MAX(ABS($C4-$D4),1)=(HF4-HG4)/MAX(ABS(HF4-HG4),1),1,TRUE,0)} | HK4: {=_xlfn.IFS($D4="","",AND(HI4=$C4,HJ4=$D4),3,($C4-$D4)/MAX(ABS($C4-$D4),1)=(HI4-HJ4)/MAX(ABS(HI4-HJ4),1),1,TRUE,0)} | HN4: {=_xlfn.IFS($D4="","",AND(HL4=$C4,HM4=$D4),3,($C4-$D4)/MAX(ABS($C4-$D4),1)=(HL4-HM4)/MAX(ABS(HL4-HM4),1),1,TRUE,0)} | HQ4: {=_xlfn.IFS($D4="","",AND(HO4=$C4,HP4=$D4),3,($C4-$D4)/MAX(ABS($C4-$D4),1)=(HO4-HP4)/MAX(ABS(HO4-HP4),1),1,TRUE,0)} | HT4: {=_xlfn.IFS($D4="","",AND(HR4=$C4,HS4=$D4),3,($C4-$D4)/MAX(ABS($C4-$D4),1)=(HR4-HS4)/MAX(ABS(HR4-HS4),1),1,TRUE,0)} | HW4: {=_xlfn.IFS($D4="","",AND(HU4=$C4,HV4=$D4),3,($C4-$D4)/MAX(ABS($C4-$D4),1)=(HU4-HV4)/MAX(ABS(HU4-HV4),1),1,TRUE,0)} | HZ4: {=_xlfn.IFS($D4="","",AND(HX4=$C4,HY4=$D4),3,($C4-$D4)/MAX(ABS($C4-$D4),1)=(HX4-HY4)/MAX(ABS(HX4-HY4),1),1,TRUE,0)} | IC4: {=_xlfn.IFS($D4="","",AND(IA4=$C4,IB4=$D4),3,($C4-$D4)/MAX(ABS($C4-$D4),1)=(IA4-IB4)/MAX(ABS(IA4-IB4),1),1,TRUE,0)} | IF4: {=_xlfn.IFS($D4="","",AND(ID4=$C4,IE4=$D4),3,($C4-$D4)/MAX(ABS($C4-$D4),1)=(ID4-IE4)/MAX(ABS(ID4-IE4),1),1,TRUE,0)} | II4: {=_xlfn.IFS($D4="","",AND(IG4=$C4,IH4=$D4),3,($C4-$D4)/MAX(ABS($C4-$D4),1)=(IG4-IH4)/MAX(ABS(IG4-IH4),1),1,TRUE,0)} | IL4: {=_xlfn.IFS($D4="","",AND(IJ4=$C4,IK4=$D4),3,($C4-$D4)/MAX(ABS($C4-$D4),1)=(IJ4-IK4)/MAX(ABS(IJ4-IK4),1),1,TRUE,0)} | IO4: {=_xlfn.IFS($D4="","",AND(IM4=$C4,IN4=$D4),3,($C4-$D4)/MAX(ABS($C4-$D4),1)=(IM4-IN4)/MAX(ABS(IM4-IN4),1),1,TRUE,0)} | IR4: {=_xlfn.IFS($D4="","",AND(IP4=$C4,IQ4=$D4),3,($C4-$D4)/MAX(ABS($C4-$D4),1)=(IP4-IQ4)/MAX(ABS(IP4-IQ4),1),1,TRUE,0)} | IU4: {=_xlfn.IFS($D4="","",AND(IS4=$C4,IT4=$D4),3,($C4-$D4)/MAX(ABS($C4-$D4),1)=(IS4-IT4)/MAX(ABS(IS4-IT4),1),1,TRUE,0)} | IX4: {=_xlfn.IFS($D4="","",AND(IV4=$C4,IW4=$D4),3,($C4-$D4)/MAX(ABS($C4-$D4),1)=(IV4-IW4)/MAX(ABS(IV4-IW4),1),1,TRUE,0)} | JA4: {=_xlfn.IFS($D4="","",AND(IY4=$C4,IZ4=$D4),3,($C4-$D4)/MAX(ABS($C4-$D4),1)=(IY4-IZ4)/MAX(ABS(IY4-IZ4),1),1,TRUE,0)} | JD4: {=_xlfn.IFS($D4="","",AND(JB4=$C4,JC4=$D4),3,($C4-$D4)/MAX(ABS($C4-$D4),1)=(JB4-JC4)/MAX(ABS(JB4-JC4),1),1,TRUE,0)}
A5: 46185 | B5: Canada | C5: {=_xlfn.LET( _xlpm.x,_xlfn.XLOOKUP(1,(Scores_Fixtures[Date]=A5)*(Scores_Fixtures[Home.1]=B5),Scores_Fixtures[Score.1],""), IF(_xlpm.x="","",_xlpm.x) )} | D5: {=_xlfn.LET( _xlpm.x,_xlfn.XLOOKUP(1,(Scores_Fixtures[Date]=A5)*(Scores_Fixtures[Home.1]=B5),Scores_Fixtures[Score.2],""), IF(_xlpm.x="","",_xlpm.x) )} | E5: Bosnia Herzeg. | I5: {=_xlfn.IFS($D5="","",AND(G5=$C5,H5=$D5),3,($C5-$D5)/MAX(ABS($C5-$D5),1)=(G5-H5)/MAX(ABS(G5-H5),1),1,TRUE,0)} | L5: {=_xlfn.IFS($D5="","",AND(J5=$C5,K5=$D5),3,($C5-$D5)/MAX(ABS($C5-$D5),1)=(J5-K5)/MAX(ABS(J5-K5),1),1,TRUE,0)} | O5: {=_xlfn.IFS($D5="","",AND(M5=$C5,N5=$D5),3,($C5-$D5)/MAX(ABS($C5-$D5),1)=(M5-N5)/MAX(ABS(M5-N5),1),1,TRUE,0)} | R5: {=_xlfn.IFS($D5="","",AND(P5=$C5,Q5=$D5),3,($C5-$D5)/MAX(ABS($C5-$D5),1)=(P5-Q5)/MAX(ABS(P5-Q5),1),1,TRUE,0)} | U5: {=_xlfn.IFS($D5="","",AND(S5=$C5,T5=$D5),3,($C5-$D5)/MAX(ABS($C5-$D5),1)=(S5-T5)/MAX(ABS(S5-T5),1),1,TRUE,0)} | X5: {=_xlfn.IFS($D5="","",AND(V5=$C5,W5=$D5),3,($C5-$D5)/MAX(ABS($C5-$D5),1)=(V5-W5)/MAX(ABS(V5-W5),1),1,TRUE,0)} | AA5: {=_xlfn.IFS($D5="","",AND(Y5=$C5,Z5=$D5),3,($C5-$D5)/MAX(ABS($C5-$D5),1)=(Y5-Z5)/MAX(ABS(Y5-Z5),1),1,TRUE,0)} | AD5: {=_xlfn.IFS($D5="","",AND(AB5=$C5,AC5=$D5),3,($C5-$D5)/MAX(ABS($C5-$D5),1)=(AB5-AC5)/MAX(ABS(AB5-AC5),1),1,TRUE,0)} | AG5: {=_xlfn.IFS($D5="","",AND(AE5=$C5,AF5=$D5),3,($C5-$D5)/MAX(ABS($C5-$D5),1)=(AE5-AF5)/MAX(ABS(AE5-AF5),1),1,TRUE,0)} | AJ5: {=_xlfn.IFS($D5="","",AND(AH5=$C5,AI5=$D5),3,($C5-$D5)/MAX(ABS($C5-$D5),1)=(AH5-AI5)/MAX(ABS(AH5-AI5),1),1,TRUE,0)} | AM5: {=_xlfn.IFS($D5="","",AND(AK5=$C5,AL5=$D5),3,($C5-$D5)/MAX(ABS($C5-$D5),1)=(AK5-AL5)/MAX(ABS(AK5-AL5),1),1,TRUE,0)} | AP5: {=_xlfn.IFS($D5="","",AND(AN5=$C5,AO5=$D5),3,($C5-$D5)/MAX(ABS($C5-$D5),1)=(AN5-AO5)/MAX(ABS(AN5-AO5),1),1,TRUE,0)} | AS5: {=_xlfn.IFS($D5="","",AND(AQ5=$C5,AR5=$D5),3,($C5-$D5)/MAX(ABS($C5-$D5),1)=(AQ5-AR5)/MAX(ABS(AQ5-AR5),1),1,TRUE,0)} | AV5: {=_xlfn.IFS($D5="","",AND(AT5=$C5,AU5=$D5),3,($C5-$D5)/MAX(ABS($C5-$D5),1)=(AT5-AU5)/MAX(ABS(AT5-AU5),1),1,TRUE,0)} | AY5: {=_xlfn.IFS($D5="","",AND(AW5=$C5,AX5=$D5),3,($C5-$D5)/MAX(ABS($C5-$D5),1)=(AW5-AX5)/MAX(ABS(AW5-AX5),1),1,TRUE,0)} | BB5: {=_xlfn.IFS($D5="","",AND(AZ5=$C5,BA5=$D5),3,($C5-$D5)/MAX(ABS($C5-$D5),1)=(AZ5-BA5)/MAX(ABS(AZ5-BA5),1),1,TRUE,0)} | BE5: {=_xlfn.IFS($D5="","",AND(BC5=$C5,BD5=$D5),3,($C5-$D5)/MAX(ABS($C5-$D5),1)=(BC5-BD5)/MAX(ABS(BC5-BD5),1),1,TRUE,0)} | BH5: {=_xlfn.IFS($D5="","",AND(BF5=$C5,BG5=$D5),3,($C5-$D5)/MAX(ABS($C5-$D5),1)=(BF5-BG5)/MAX(ABS(BF5-BG5),1),1,TRUE,0)} | BK5: {=_xlfn.IFS($D5="","",AND(BI5=$C5,BJ5=$D5),3,($C5-$D5)/MAX(ABS($C5-$D5),1)=(BI5-BJ5)/MAX(ABS(BI5-BJ5),1),1,TRUE,0)} | BN5: {=_xlfn.IFS($D5="","",AND(BL5=$C5,BM5=$D5),3,($C5-$D5)/MAX(ABS($C5-$D5),1)=(BL5-BM5)/MAX(ABS(BL5-BM5),1),1,TRUE,0)} | BQ5: {=_xlfn.IFS($D5="","",AND(BO5=$C5,BP5=$D5),3,($C5-$D5)/MAX(ABS($C5-$D5),1)=(BO5-BP5)/MAX(ABS(BO5-BP5),1),1,TRUE,0)} | BT5: {=_xlfn.IFS($D5="","",AND(BR5=$C5,BS5=$D5),3,($C5-$D5)/MAX(ABS($C5-$D5),1)=(BR5-BS5)/MAX(ABS(BR5-BS5),1),1,TRUE,0)} | BW5: {=_xlfn.IFS($D5="","",AND(BU5=$C5,BV5=$D5),3,($C5-$D5)/MAX(ABS($C5-$D5),1)=(BU5-BV5)/MAX(ABS(BU5-BV5),1),1,TRUE,0)} | BZ5: {=_xlfn.IFS($D5="","",AND(BX5=$C5,BY5=$D5),3,($C5-$D5)/MAX(ABS($C5-$D5),1)=(BX5-BY5)/MAX(ABS(BX5-BY5),1),1,TRUE,0)} | CC5: {=_xlfn.IFS($D5="","",AND(CA5=$C5,CB5=$D5),3,($C5-$D5)/MAX(ABS($C5-$D5),1)=(CA5-CB5)/MAX(ABS(CA5-CB5),1),1,TRUE,0)} | CF5: {=_xlfn.IFS($D5="","",AND(CD5=$C5,CE5=$D5),3,($C5-$D5)/MAX(ABS($C5-$D5),1)=(CD5-CE5)/MAX(ABS(CD5-CE5),1),1,TRUE,0)} | CI5: {=_xlfn.IFS($D5="","",AND(CG5=$C5,CH5=$D5),3,($C5-$D5)/MAX(ABS($C5-$D5),1)=(CG5-CH5)/MAX(ABS(CG5-CH5),1),1,TRUE,0)} | CL5: {=_xlfn.IFS($D5="","",AND(CJ5=$C5,CK5=$D5),3,($C5-$D5)/MAX(ABS($C5-$D5),1)=(CJ5-CK5)/MAX(ABS(CJ5-CK5),1),1,TRUE,0)} | CO5: {=_xlfn.IFS($D5="","",AND(CM5=$C5,CN5=$D5),3,($C5-$D5)/MAX(ABS($C5-$D5),1)=(CM5-CN5)/MAX(ABS(CM5-CN5),1),1,TRUE,0)} | CR5: {=_xlfn.IFS($D5="","",AND(CP5=$C5,CQ5=$D5),3,($C5-$D5)/MAX(ABS($C5-$D5),1)=(CP5-CQ5)/MAX(ABS(CP5-CQ5),1),1,TRUE,0)} | CU5: {=_xlfn.IFS($D5="","",AND(CS5=$C5,CT5=$D5),3,($C5-$D5)/MAX(ABS($C5-$D5),1)=(CS5-CT5)/MAX(ABS(CS5-CT5),1),1,TRUE,0)} | CX5: {=_xlfn.IFS($D5="","",AND(CV5=$C5,CW5=$D5),3,($C5-$D5)/MAX(ABS($C5-$D5),1)=(CV5-CW5)/MAX(ABS(CV5-CW5),1),1,TRUE,0)} | DA5: {=_xlfn.IFS($D5="","",AND(CY5=$C5,CZ5=$D5),3,($C5-$D5)/MAX(ABS($C5-$D5),1)=(CY5-CZ5)/MAX(ABS(CY5-CZ5),1),1,TRUE,0)} | DD5: {=_xlfn.IFS($D5="","",AND(DB5=$C5,DC5=$D5),3,($C5-$D5)/MAX(ABS($C5-$D5),1)=(DB5-DC5)/MAX(ABS(DB5-DC5),1),1,TRUE,0)} | DG5: {=_xlfn.IFS($D5="","",AND(DE5=$C5,DF5=$D5),3,($C5-$D5)/MAX(ABS($C5-$D5),1)=(DE5-DF5)/MAX(ABS(DE5-DF5),1),1,TRUE,0)} | DJ5: {=_xlfn.IFS($D5="","",AND(DH5=$C5,DI5=$D5),3,($C5-$D5)/MAX(ABS($C5-$D5),1)=(DH5-DI5)/MAX(ABS(DH5-DI5),1),1,TRUE,0)} | DM5: {=_xlfn.IFS($D5="","",AND(DK5=$C5,DL5=$D5),3,($C5-$D5)/MAX(ABS($C5-$D5),1)=(DK5-DL5)/MAX(ABS(DK5-DL5),1),1,TRUE,0)} | DP5: {=_xlfn.IFS($D5="","",AND(DN5=$C5,DO5=$D5),3,($C5-$D5)/MAX(ABS($C5-$D5),1)=(DN5-DO5)/MAX(ABS(DN5-DO5),1),1,TRUE,0)} | DS5: {=_xlfn.IFS($D5="","",AND(DQ5=$C5,DR5=$D5),3,($C5-$D5)/MAX(ABS($C5-$D5),1)=(DQ5-DR5)/MAX(ABS(DQ5-DR5),1),1,TRUE,0)} | DV5: {=_xlfn.IFS($D5="","",AND(DT5=$C5,DU5=$D5),3,($C5-$D5)/MAX(ABS($C5-$D5),1)=(DT5-DU5)/MAX(ABS(DT5-DU5),1),1,TRUE,0)} | DY5: {=_xlfn.IFS($D5="","",AND(DW5=$C5,DX5=$D5),3,($C5-$D5)/MAX(ABS($C5-$D5),1)=(DW5-DX5)/MAX(ABS(DW5-DX5),1),1,TRUE,0)} | EB5: {=_xlfn.IFS($D5="","",AND(DZ5=$C5,EA5=$D5),3,($C5-$D5)/MAX(ABS($C5-$D5),1)=(DZ5-EA5)/MAX(ABS(DZ5-EA5),1),1,TRUE,0)} | EE5: {=_xlfn.IFS($D5="","",AND(EC5=$C5,ED5=$D5),3,($C5-$D5)/MAX(ABS($C5-$D5),1)=(EC5-ED5)/MAX(ABS(EC5-ED5),1),1,TRUE,0)} | EH5: {=_xlfn.IFS($D5="","",AND(EF5=$C5,EG5=$D5),3,($C5-$D5)/MAX(ABS($C5-$D5),1)=(EF5-EG5)/MAX(ABS(EF5-EG5),1),1,TRUE,0)} | EK5: {=_xlfn.IFS($D5="","",AND(EI5=$C5,EJ5=$D5),3,($C5-$D5)/MAX(ABS($C5-$D5),1)=(EI5-EJ5)/MAX(ABS(EI5-EJ5),1),1,TRUE,0)} | EN5: {=_xlfn.IFS($D5="","",AND(EL5=$C5,EM5=$D5),3,($C5-$D5)/MAX(ABS($C5-$D5),1)=(EL5-EM5)/MAX(ABS(EL5-EM5),1),1,TRUE,0)} | EQ5: {=_xlfn.IFS($D5="","",AND(EO5=$C5,EP5=$D5),3,($C5-$D5)/MAX(ABS($C5-$D5),1)=(EO5-EP5)/MAX(ABS(EO5-EP5),1),1,TRUE,0)} | ET5: {=_xlfn.IFS($D5="","",AND(ER5=$C5,ES5=$D5),3,($C5-$D5)/MAX(ABS($C5-$D5),1)=(ER5-ES5)/MAX(ABS(ER5-ES5),1),1,TRUE,0)} | EW5: {=_xlfn.IFS($D5="","",AND(EU5=$C5,EV5=$D5),3,($C5-$D5)/MAX(ABS($C5-$D5),1)=(EU5-EV5)/MAX(ABS(EU5-EV5),1),1,TRUE,0)} | EZ5: {=_xlfn.IFS($D5="","",AND(EX5=$C5,EY5=$D5),3,($C5-$D5)/MAX(ABS($C5-$D5),1)=(EX5-EY5)/MAX(ABS(EX5-EY5),1),1,TRUE,0)} | FC5: {=_xlfn.IFS($D5="","",AND(FA5=$C5,FB5=$D5),3,($C5-$D5)/MAX(ABS($C5-$D5),1)=(FA5-FB5)/MAX(ABS(FA5-FB5),1),1,TRUE,0)} | FF5: {=_xlfn.IFS($D5="","",AND(FD5=$C5,FE5=$D5),3,($C5-$D5)/MAX(ABS($C5-$D5),1)=(FD5-FE5)/MAX(ABS(FD5-FE5),1),1,TRUE,0)} | FI5: {=_xlfn.IFS($D5="","",AND(FG5=$C5,FH5=$D5),3,($C5-$D5)/MAX(ABS($C5-$D5),1)=(FG5-FH5)/MAX(ABS(FG5-FH5),1),1,TRUE,0)} | FL5: {=_xlfn.IFS($D5="","",AND(FJ5=$C5,FK5=$D5),3,($C5-$D5)/MAX(ABS($C5-$D5),1)=(FJ5-FK5)/MAX(ABS(FJ5-FK5),1),1,TRUE,0)} | FO5: {=_xlfn.IFS($D5="","",AND(FM5=$C5,FN5=$D5),3,($C5-$D5)/MAX(ABS($C5-$D5),1)=(FM5-FN5)/MAX(ABS(FM5-FN5),1),1,TRUE,0)} | FR5: {=_xlfn.IFS($D5="","",AND(FP5=$C5,FQ5=$D5),3,($C5-$D5)/MAX(ABS($C5-$D5),1)=(FP5-FQ5)/MAX(ABS(FP5-FQ5),1),1,TRUE,0)} | FU5: {=_xlfn.IFS($D5="","",AND(FS5=$C5,FT5=$D5),3,($C5-$D5)/MAX(ABS($C5-$D5),1)=(FS5-FT5)/MAX(ABS(FS5-FT5),1),1,TRUE,0)} | FX5: {=_xlfn.IFS($D5="","",AND(FV5=$C5,FW5=$D5),3,($C5-$D5)/MAX(ABS($C5-$D5),1)=(FV5-FW5)/MAX(ABS(FV5-FW5),1),1,TRUE,0)} | GA5: {=_xlfn.IFS($D5="","",AND(FY5=$C5,FZ5=$D5),3,($C5-$D5)/MAX(ABS($C5-$D5),1)=(FY5-FZ5)/MAX(ABS(FY5-FZ5),1),1,TRUE,0)} | GD5: {=_xlfn.IFS($D5="","",AND(GB5=$C5,GC5=$D5),3,($C5-$D5)/MAX(ABS($C5-$D5),1)=(GB5-GC5)/MAX(ABS(GB5-GC5),1),1,TRUE,0)} | GG5: {=_xlfn.IFS($D5="","",AND(GE5=$C5,GF5=$D5),3,($C5-$D5)/MAX(ABS($C5-$D5),1)=(GE5-GF5)/MAX(ABS(GE5-GF5),1),1,TRUE,0)} | GJ5: {=_xlfn.IFS($D5="","",AND(GH5=$C5,GI5=$D5),3,($C5-$D5)/MAX(ABS($C5-$D5),1)=(GH5-GI5)/MAX(ABS(GH5-GI5),1),1,TRUE,0)} | GM5: {=_xlfn.IFS($D5="","",AND(GK5=$C5,GL5=$D5),3,($C5-$D5)/MAX(ABS($C5-$D5),1)=(GK5-GL5)/MAX(ABS(GK5-GL5),1),1,TRUE,0)} | GP5: {=_xlfn.IFS($D5="","",AND(GN5=$C5,GO5=$D5),3,($C5-$D5)/MAX(ABS($C5-$D5),1)=(GN5-GO5)/MAX(ABS(GN5-GO5),1),1,TRUE,0)} | GS5: {=_xlfn.IFS($D5="","",AND(GQ5=$C5,GR5=$D5),3,($C5-$D5)/MAX(ABS($C5-$D5),1)=(GQ5-GR5)/MAX(ABS(GQ5-GR5),1),1,TRUE,0)} | GV5: {=_xlfn.IFS($D5="","",AND(GT5=$C5,GU5=$D5),3,($C5-$D5)/MAX(ABS($C5-$D5),1)=(GT5-GU5)/MAX(ABS(GT5-GU5),1),1,TRUE,0)} | GY5: {=_xlfn.IFS($D5="","",AND(GW5=$C5,GX5=$D5),3,($C5-$D5)/MAX(ABS($C5-$D5),1)=(GW5-GX5)/MAX(ABS(GW5-GX5),1),1,TRUE,0)} | HB5: {=_xlfn.IFS($D5="","",AND(GZ5=$C5,HA5=$D5),3,($C5-$D5)/MAX(ABS($C5-$D5),1)=(GZ5-HA5)/MAX(ABS(GZ5-HA5),1),1,TRUE,0)} | HE5: {=_xlfn.IFS($D5="","",AND(HC5=$C5,HD5=$D5),3,($C5-$D5)/MAX(ABS($C5-$D5),1)=(HC5-HD5)/MAX(ABS(HC5-HD5),1),1,TRUE,0)} | HH5: {=_xlfn.IFS($D5="","",AND(HF5=$C5,HG5=$D5),3,($C5-$D5)/MAX(ABS($C5-$D5),1)=(HF5-HG5)/MAX(ABS(HF5-HG5),1),1,TRUE,0)} | HK5: {=_xlfn.IFS($D5="","",AND(HI5=$C5,HJ5=$D5),3,($C5-$D5)/MAX(ABS($C5-$D5),1)=(HI5-HJ5)/MAX(ABS(HI5-HJ5),1),1,TRUE,0)} | HN5: {=_xlfn.IFS($D5="","",AND(HL5=$C5,HM5=$D5),3,($C5-$D5)/MAX(ABS($C5-$D5),1)=(HL5-HM5)/MAX(ABS(HL5-HM5),1),1,TRUE,0)} | HQ5: {=_xlfn.IFS($D5="","",AND(HO5=$C5,HP5=$D5),3,($C5-$D5)/MAX(ABS($C5-$D5),1)=(HO5-HP5)/MAX(ABS(HO5-HP5),1),1,TRUE,0)} | HT5: {=_xlfn.IFS($D5="","",AND(HR5=$C5,HS5=$D5),3,($C5-$D5)/MAX(ABS($C5-$D5),1)=(HR5-HS5)/MAX(ABS(HR5-HS5),1),1,TRUE,0)} | HW5: {=_xlfn.IFS($D5="","",AND(HU5=$C5,HV5=$D5),3,($C5-$D5)/MAX(ABS($C5-$D5),1)=(HU5-HV5)/MAX(ABS(HU5-HV5),1),1,TRUE,0)} | HZ5: {=_xlfn.IFS($D5="","",AND(HX5=$C5,HY5=$D5),3,($C5-$D5)/MAX(ABS($C5-$D5),1)=(HX5-HY5)/MAX(ABS(HX5-HY5),1),1,TRUE,0)} | IC5: {=_xlfn.IFS($D5="","",AND(IA5=$C5,IB5=$D5),3,($C5-$D5)/MAX(ABS($C5-$D5),1)=(IA5-IB5)/MAX(ABS(IA5-IB5),1),1,TRUE,0)} | IF5: {=_xlfn.IFS($D5="","",AND(ID5=$C5,IE5=$D5),3,($C5-$D5)/MAX(ABS($C5-$D5),1)=(ID5-IE5)/MAX(ABS(ID5-IE5),1),1,TRUE,0)} | II5: {=_xlfn.IFS($D5="","",AND(IG5=$C5,IH5=$D5),3,($C5-$D5)/MAX(ABS($C5-$D5),1)=(IG5-IH5)/MAX(ABS(IG5-IH5),1),1,TRUE,0)} | IL5: {=_xlfn.IFS($D5="","",AND(IJ5=$C5,IK5=$D5),3,($C5-$D5)/MAX(ABS($C5-$D5),1)=(IJ5-IK5)/MAX(ABS(IJ5-IK5),1),1,TRUE,0)} | IO5: {=_xlfn.IFS($D5="","",AND(IM5=$C5,IN5=$D5),3,($C5-$D5)/MAX(ABS($C5-$D5),1)=(IM5-IN5)/MAX(ABS(IM5-IN5),1),1,TRUE,0)} | IR5: {=_xlfn.IFS($D5="","",AND(IP5=$C5,IQ5=$D5),3,($C5-$D5)/MAX(ABS($C5-$D5),1)=(IP5-IQ5)/MAX(ABS(IP5-IQ5),1),1,TRUE,0)} | IU5: {=_xlfn.IFS($D5="","",AND(IS5=$C5,IT5=$D5),3,($C5-$D5)/MAX(ABS($C5-$D5),1)=(IS5-IT5)/MAX(ABS(IS5-IT5),1),1,TRUE,0)} | IX5: {=_xlfn.IFS($D5="","",AND(IV5=$C5,IW5=$D5),3,($C5-$D5)/MAX(ABS($C5-$D5),1)=(IV5-IW5)/MAX(ABS(IV5-IW5),1),1,TRUE,0)} | JA5: {=_xlfn.IFS($D5="","",AND(IY5=$C5,IZ5=$D5),3,($C5-$D5)/MAX(ABS($C5-$D5),1)=(IY5-IZ5)/MAX(ABS(IY5-IZ5),1),1,TRUE,0)} | JD5: {=_xlfn.IFS($D5="","",AND(JB5=$C5,JC5=$D5),3,($C5-$D5)/MAX(ABS($C5-$D5),1)=(JB5-JC5)/MAX(ABS(JB5-JC5),1),1,TRUE,0)}
A6: 46186 | B6: USA | C6: {=_xlfn.LET( _xlpm.x,_xlfn.XLOOKUP(1,(Scores_Fixtures[Date]=A6)*(Scores_Fixtures[Home.1]=B6),Scores_Fixtures[Score.1],""), IF(_xlpm.x="","",_xlpm.x) )} | D6: {=_xlfn.LET( _xlpm.x,_xlfn.XLOOKUP(1,(Scores_Fixtures[Date]=A6)*(Scores_Fixtures[Home.1]=B6),Scores_Fixtures[Score.2],""), IF(_xlpm.x="","",_xlpm.x) )} | E6: Paraguay | I6: {=_xlfn.IFS($D6="","",AND(G6=$C6,H6=$D6),3,($C6-$D6)/MAX(ABS($C6-$D6),1)=(G6-H6)/MAX(ABS(G6-H6),1),1,TRUE,0)} | L6: {=_xlfn.IFS($D6="","",AND(J6=$C6,K6=$D6),3,($C6-$D6)/MAX(ABS($C6-$D6),1)=(J6-K6)/MAX(ABS(J6-K6),1),1,TRUE,0)} | O6: {=_xlfn.IFS($D6="","",AND(M6=$C6,N6=$D6),3,($C6-$D6)/MAX(ABS($C6-$D6),1)=(M6-N6)/MAX(ABS(M6-N6),1),1,TRUE,0)} | R6: {=_xlfn.IFS($D6="","",AND(P6=$C6,Q6=$D6),3,($C6-$D6)/MAX(ABS($C6-$D6),1)=(P6-Q6)/MAX(ABS(P6-Q6),1),1,TRUE,0)} | U6: {=_xlfn.IFS($D6="","",AND(S6=$C6,T6=$D6),3,($C6-$D6)/MAX(ABS($C6-$D6),1)=(S6-T6)/MAX(ABS(S6-T6),1),1,TRUE,0)} | X6: {=_xlfn.IFS($D6="","",AND(V6=$C6,W6=$D6),3,($C6-$D6)/MAX(ABS($C6-$D6),1)=(V6-W6)/MAX(ABS(V6-W6),1),1,TRUE,0)} | AA6: {=_xlfn.IFS($D6="","",AND(Y6=$C6,Z6=$D6),3,($C6-$D6)/MAX(ABS($C6-$D6),1)=(Y6-Z6)/MAX(ABS(Y6-Z6),1),1,TRUE,0)} | AD6: {=_xlfn.IFS($D6="","",AND(AB6=$C6,AC6=$D6),3,($C6-$D6)/MAX(ABS($C6-$D6),1)=(AB6-AC6)/MAX(ABS(AB6-AC6),1),1,TRUE,0)} | AG6: {=_xlfn.IFS($D6="","",AND(AE6=$C6,AF6=$D6),3,($C6-$D6)/MAX(ABS($C6-$D6),1)=(AE6-AF6)/MAX(ABS(AE6-AF6),1),1,TRUE,0)} | AJ6: {=_xlfn.IFS($D6="","",AND(AH6=$C6,AI6=$D6),3,($C6-$D6)/MAX(ABS($C6-$D6),1)=(AH6-AI6)/MAX(ABS(AH6-AI6),1),1,TRUE,0)} | AM6: {=_xlfn.IFS($D6="","",AND(AK6=$C6,AL6=$D6),3,($C6-$D6)/MAX(ABS($C6-$D6),1)=(AK6-AL6)/MAX(ABS(AK6-AL6),1),1,TRUE,0)} | AP6: {=_xlfn.IFS($D6="","",AND(AN6=$C6,AO6=$D6),3,($C6-$D6)/MAX(ABS($C6-$D6),1)=(AN6-AO6)/MAX(ABS(AN6-AO6),1),1,TRUE,0)} | AS6: {=_xlfn.IFS($D6="","",AND(AQ6=$C6,AR6=$D6),3,($C6-$D6)/MAX(ABS($C6-$D6),1)=(AQ6-AR6)/MAX(ABS(AQ6-AR6),1),1,TRUE,0)} | AV6: {=_xlfn.IFS($D6="","",AND(AT6=$C6,AU6=$D6),3,($C6-$D6)/MAX(ABS($C6-$D6),1)=(AT6-AU6)/MAX(ABS(AT6-AU6),1),1,TRUE,0)} | AY6: {=_xlfn.IFS($D6="","",AND(AW6=$C6,AX6=$D6),3,($C6-$D6)/MAX(ABS($C6-$D6),1)=(AW6-AX6)/MAX(ABS(AW6-AX6),1),1,TRUE,0)} | BB6: {=_xlfn.IFS($D6="","",AND(AZ6=$C6,BA6=$D6),3,($C6-$D6)/MAX(ABS($C6-$D6),1)=(AZ6-BA6)/MAX(ABS(AZ6-BA6),1),1,TRUE,0)} | BE6: {=_xlfn.IFS($D6="","",AND(BC6=$C6,BD6=$D6),3,($C6-$D6)/MAX(ABS($C6-$D6),1)=(BC6-BD6)/MAX(ABS(BC6-BD6),1),1,TRUE,0)} | BH6: {=_xlfn.IFS($D6="","",AND(BF6=$C6,BG6=$D6),3,($C6-$D6)/MAX(ABS($C6-$D6),1)=(BF6-BG6)/MAX(ABS(BF6-BG6),1),1,TRUE,0)} | BK6: {=_xlfn.IFS($D6="","",AND(BI6=$C6,BJ6=$D6),3,($C6-$D6)/MAX(ABS($C6-$D6),1)=(BI6-BJ6)/MAX(ABS(BI6-BJ6),1),1,TRUE,0)} | BN6: {=_xlfn.IFS($D6="","",AND(BL6=$C6,BM6=$D6),3,($C6-$D6)/MAX(ABS($C6-$D6),1)=(BL6-BM6)/MAX(ABS(BL6-BM6),1),1,TRUE,0)} | BQ6: {=_xlfn.IFS($D6="","",AND(BO6=$C6,BP6=$D6),3,($C6-$D6)/MAX(ABS($C6-$D6),1)=(BO6-BP6)/MAX(ABS(BO6-BP6),1),1,TRUE,0)} | BT6: {=_xlfn.IFS($D6="","",AND(BR6=$C6,BS6=$D6),3,($C6-$D6)/MAX(ABS($C6-$D6),1)=(BR6-BS6)/MAX(ABS(BR6-BS6),1),1,TRUE,0)} | BW6: {=_xlfn.IFS($D6="","",AND(BU6=$C6,BV6=$D6),3,($C6-$D6)/MAX(ABS($C6-$D6),1)=(BU6-BV6)/MAX(ABS(BU6-BV6),1),1,TRUE,0)} | BZ6: {=_xlfn.IFS($D6="","",AND(BX6=$C6,BY6=$D6),3,($C6-$D6)/MAX(ABS($C6-$D6),1)=(BX6-BY6)/MAX(ABS(BX6-BY6),1),1,TRUE,0)} | CC6: {=_xlfn.IFS($D6="","",AND(CA6=$C6,CB6=$D6),3,($C6-$D6)/MAX(ABS($C6-$D6),1)=(CA6-CB6)/MAX(ABS(CA6-CB6),1),1,TRUE,0)} | CF6: {=_xlfn.IFS($D6="","",AND(CD6=$C6,CE6=$D6),3,($C6-$D6)/MAX(ABS($C6-$D6),1)=(CD6-CE6)/MAX(ABS(CD6-CE6),1),1,TRUE,0)} | CI6: {=_xlfn.IFS($D6="","",AND(CG6=$C6,CH6=$D6),3,($C6-$D6)/MAX(ABS($C6-$D6),1)=(CG6-CH6)/MAX(ABS(CG6-CH6),1),1,TRUE,0)} | CL6: {=_xlfn.IFS($D6="","",AND(CJ6=$C6,CK6=$D6),3,($C6-$D6)/MAX(ABS($C6-$D6),1)=(CJ6-CK6)/MAX(ABS(CJ6-CK6),1),1,TRUE,0)} | CO6: {=_xlfn.IFS($D6="","",AND(CM6=$C6,CN6=$D6),3,($C6-$D6)/MAX(ABS($C6-$D6),1)=(CM6-CN6)/MAX(ABS(CM6-CN6),1),1,TRUE,0)} | CR6: {=_xlfn.IFS($D6="","",AND(CP6=$C6,CQ6=$D6),3,($C6-$D6)/MAX(ABS($C6-$D6),1)=(CP6-CQ6)/MAX(ABS(CP6-CQ6),1),1,TRUE,0)} | CU6: {=_xlfn.IFS($D6="","",AND(CS6=$C6,CT6=$D6),3,($C6-$D6)/MAX(ABS($C6-$D6),1)=(CS6-CT6)/MAX(ABS(CS6-CT6),1),1,TRUE,0)} | CX6: {=_xlfn.IFS($D6="","",AND(CV6=$C6,CW6=$D6),3,($C6-$D6)/MAX(ABS($C6-$D6),1)=(CV6-CW6)/MAX(ABS(CV6-CW6),1),1,TRUE,0)} | DA6: {=_xlfn.IFS($D6="","",AND(CY6=$C6,CZ6=$D6),3,($C6-$D6)/MAX(ABS($C6-$D6),1)=(CY6-CZ6)/MAX(ABS(CY6-CZ6),1),1,TRUE,0)} | DD6: {=_xlfn.IFS($D6="","",AND(DB6=$C6,DC6=$D6),3,($C6-$D6)/MAX(ABS($C6-$D6),1)=(DB6-DC6)/MAX(ABS(DB6-DC6),1),1,TRUE,0)} | DG6: {=_xlfn.IFS($D6="","",AND(DE6=$C6,DF6=$D6),3,($C6-$D6)/MAX(ABS($C6-$D6),1)=(DE6-DF6)/MAX(ABS(DE6-DF6),1),1,TRUE,0)} | DJ6: {=_xlfn.IFS($D6="","",AND(DH6=$C6,DI6=$D6),3,($C6-$D6)/MAX(ABS($C6-$D6),1)=(DH6-DI6)/MAX(ABS(DH6-DI6),1),1,TRUE,0)} | DM6: {=_xlfn.IFS($D6="","",AND(DK6=$C6,DL6=$D6),3,($C6-$D6)/MAX(ABS($C6-$D6),1)=(DK6-DL6)/MAX(ABS(DK6-DL6),1),1,TRUE,0)} | DP6: {=_xlfn.IFS($D6="","",AND(DN6=$C6,DO6=$D6),3,($C6-$D6)/MAX(ABS($C6-$D6),1)=(DN6-DO6)/MAX(ABS(DN6-DO6),1),1,TRUE,0)} | DS6: {=_xlfn.IFS($D6="","",AND(DQ6=$C6,DR6=$D6),3,($C6-$D6)/MAX(ABS($C6-$D6),1)=(DQ6-DR6)/MAX(ABS(DQ6-DR6),1),1,TRUE,0)} | DV6: {=_xlfn.IFS($D6="","",AND(DT6=$C6,DU6=$D6),3,($C6-$D6)/MAX(ABS($C6-$D6),1)=(DT6-DU6)/MAX(ABS(DT6-DU6),1),1,TRUE,0)} | DY6: {=_xlfn.IFS($D6="","",AND(DW6=$C6,DX6=$D6),3,($C6-$D6)/MAX(ABS($C6-$D6),1)=(DW6-DX6)/MAX(ABS(DW6-DX6),1),1,TRUE,0)} | EB6: {=_xlfn.IFS($D6="","",AND(DZ6=$C6,EA6=$D6),3,($C6-$D6)/MAX(ABS($C6-$D6),1)=(DZ6-EA6)/MAX(ABS(DZ6-EA6),1),1,TRUE,0)} | EE6: {=_xlfn.IFS($D6="","",AND(EC6=$C6,ED6=$D6),3,($C6-$D6)/MAX(ABS($C6-$D6),1)=(EC6-ED6)/MAX(ABS(EC6-ED6),1),1,TRUE,0)} | EH6: {=_xlfn.IFS($D6="","",AND(EF6=$C6,EG6=$D6),3,($C6-$D6)/MAX(ABS($C6-$D6),1)=(EF6-EG6)/MAX(ABS(EF6-EG6),1),1,TRUE,0)} | EK6: {=_xlfn.IFS($D6="","",AND(EI6=$C6,EJ6=$D6),3,($C6-$D6)/MAX(ABS($C6-$D6),1)=(EI6-EJ6)/MAX(ABS(EI6-EJ6),1),1,TRUE,0)} | EN6: {=_xlfn.IFS($D6="","",AND(EL6=$C6,EM6=$D6),3,($C6-$D6)/MAX(ABS($C6-$D6),1)=(EL6-EM6)/MAX(ABS(EL6-EM6),1),1,TRUE,0)} | EQ6: {=_xlfn.IFS($D6="","",AND(EO6=$C6,EP6=$D6),3,($C6-$D6)/MAX(ABS($C6-$D6),1)=(EO6-EP6)/MAX(ABS(EO6-EP6),1),1,TRUE,0)} | ET6: {=_xlfn.IFS($D6="","",AND(ER6=$C6,ES6=$D6),3,($C6-$D6)/MAX(ABS($C6-$D6),1)=(ER6-ES6)/MAX(ABS(ER6-ES6),1),1,TRUE,0)} | EW6: {=_xlfn.IFS($D6="","",AND(EU6=$C6,EV6=$D6),3,($C6-$D6)/MAX(ABS($C6-$D6),1)=(EU6-EV6)/MAX(ABS(EU6-EV6),1),1,TRUE,0)} | EZ6: {=_xlfn.IFS($D6="","",AND(EX6=$C6,EY6=$D6),3,($C6-$D6)/MAX(ABS($C6-$D6),1)=(EX6-EY6)/MAX(ABS(EX6-EY6),1),1,TRUE,0)} | FC6: {=_xlfn.IFS($D6="","",AND(FA6=$C6,FB6=$D6),3,($C6-$D6)/MAX(ABS($C6-$D6),1)=(FA6-FB6)/MAX(ABS(FA6-FB6),1),1,TRUE,0)} | FF6: {=_xlfn.IFS($D6="","",AND(FD6=$C6,FE6=$D6),3,($C6-$D6)/MAX(ABS($C6-$D6),1)=(FD6-FE6)/MAX(ABS(FD6-FE6),1),1,TRUE,0)} | FI6: {=_xlfn.IFS($D6="","",AND(FG6=$C6,FH6=$D6),3,($C6-$D6)/MAX(ABS($C6-$D6),1)=(FG6-FH6)/MAX(ABS(FG6-FH6),1),1,TRUE,0)} | FL6: {=_xlfn.IFS($D6="","",AND(FJ6=$C6,FK6=$D6),3,($C6-$D6)/MAX(ABS($C6-$D6),1)=(FJ6-FK6)/MAX(ABS(FJ6-FK6),1),1,TRUE,0)} | FO6: {=_xlfn.IFS($D6="","",AND(FM6=$C6,FN6=$D6),3,($C6-$D6)/MAX(ABS($C6-$D6),1)=(FM6-FN6)/MAX(ABS(FM6-FN6),1),1,TRUE,0)} | FR6: {=_xlfn.IFS($D6="","",AND(FP6=$C6,FQ6=$D6),3,($C6-$D6)/MAX(ABS($C6-$D6),1)=(FP6-FQ6)/MAX(ABS(FP6-FQ6),1),1,TRUE,0)} | FU6: {=_xlfn.IFS($D6="","",AND(FS6=$C6,FT6=$D6),3,($C6-$D6)/MAX(ABS($C6-$D6),1)=(FS6-FT6)/MAX(ABS(FS6-FT6),1),1,TRUE,0)} | FX6: {=_xlfn.IFS($D6="","",AND(FV6=$C6,FW6=$D6),3,($C6-$D6)/MAX(ABS($C6-$D6),1)=(FV6-FW6)/MAX(ABS(FV6-FW6),1),1,TRUE,0)} | GA6: {=_xlfn.IFS($D6="","",AND(FY6=$C6,FZ6=$D6),3,($C6-$D6)/MAX(ABS($C6-$D6),1)=(FY6-FZ6)/MAX(ABS(FY6-FZ6),1),1,TRUE,0)} | GD6: {=_xlfn.IFS($D6="","",AND(GB6=$C6,GC6=$D6),3,($C6-$D6)/MAX(ABS($C6-$D6),1)=(GB6-GC6)/MAX(ABS(GB6-GC6),1),1,TRUE,0)} | GG6: {=_xlfn.IFS($D6="","",AND(GE6=$C6,GF6=$D6),3,($C6-$D6)/MAX(ABS($C6-$D6),1)=(GE6-GF6)/MAX(ABS(GE6-GF6),1),1,TRUE,0)} | GJ6: {=_xlfn.IFS($D6="","",AND(GH6=$C6,GI6=$D6),3,($C6-$D6)/MAX(ABS($C6-$D6),1)=(GH6-GI6)/MAX(ABS(GH6-GI6),1),1,TRUE,0)} | GM6: {=_xlfn.IFS($D6="","",AND(GK6=$C6,GL6=$D6),3,($C6-$D6)/MAX(ABS($C6-$D6),1)=(GK6-GL6)/MAX(ABS(GK6-GL6),1),1,TRUE,0)} | GP6: {=_xlfn.IFS($D6="","",AND(GN6=$C6,GO6=$D6),3,($C6-$D6)/MAX(ABS($C6-$D6),1)=(GN6-GO6)/MAX(ABS(GN6-GO6),1),1,TRUE,0)} | GS6: {=_xlfn.IFS($D6="","",AND(GQ6=$C6,GR6=$D6),3,($C6-$D6)/MAX(ABS($C6-$D6),1)=(GQ6-GR6)/MAX(ABS(GQ6-GR6),1),1,TRUE,0)} | GV6: {=_xlfn.IFS($D6="","",AND(GT6=$C6,GU6=$D6),3,($C6-$D6)/MAX(ABS($C6-$D6),1)=(GT6-GU6)/MAX(ABS(GT6-GU6),1),1,TRUE,0)} | GY6: {=_xlfn.IFS($D6="","",AND(GW6=$C6,GX6=$D6),3,($C6-$D6)/MAX(ABS($C6-$D6),1)=(GW6-GX6)/MAX(ABS(GW6-GX6),1),1,TRUE,0)} | HB6: {=_xlfn.IFS($D6="","",AND(GZ6=$C6,HA6=$D6),3,($C6-$D6)/MAX(ABS($C6-$D6),1)=(GZ6-HA6)/MAX(ABS(GZ6-HA6),1),1,TRUE,0)} | HE6: {=_xlfn.IFS($D6="","",AND(HC6=$C6,HD6=$D6),3,($C6-$D6)/MAX(ABS($C6-$D6),1)=(HC6-HD6)/MAX(ABS(HC6-HD6),1),1,TRUE,0)} | HH6: {=_xlfn.IFS($D6="","",AND(HF6=$C6,HG6=$D6),3,($C6-$D6)/MAX(ABS($C6-$D6),1)=(HF6-HG6)/MAX(ABS(HF6-HG6),1),1,TRUE,0)} | HK6: {=_xlfn.IFS($D6="","",AND(HI6=$C6,HJ6=$D6),3,($C6-$D6)/MAX(ABS($C6-$D6),1)=(HI6-HJ6)/MAX(ABS(HI6-HJ6),1),1,TRUE,0)} | HN6: {=_xlfn.IFS($D6="","",AND(HL6=$C6,HM6=$D6),3,($C6-$D6)/MAX(ABS($C6-$D6),1)=(HL6-HM6)/MAX(ABS(HL6-HM6),1),1,TRUE,0)} | HQ6: {=_xlfn.IFS($D6="","",AND(HO6=$C6,HP6=$D6),3,($C6-$D6)/MAX(ABS($C6-$D6),1)=(HO6-HP6)/MAX(ABS(HO6-HP6),1),1,TRUE,0)} | HT6: {=_xlfn.IFS($D6="","",AND(HR6=$C6,HS6=$D6),3,($C6-$D6)/MAX(ABS($C6-$D6),1)=(HR6-HS6)/MAX(ABS(HR6-HS6),1),1,TRUE,0)} | HW6: {=_xlfn.IFS($D6="","",AND(HU6=$C6,HV6=$D6),3,($C6-$D6)/MAX(ABS($C6-$D6),1)=(HU6-HV6)/MAX(ABS(HU6-HV6),1),1,TRUE,0)} | HZ6: {=_xlfn.IFS($D6="","",AND(HX6=$C6,HY6=$D6),3,($C6-$D6)/MAX(ABS($C6-$D6),1)=(HX6-HY6)/MAX(ABS(HX6-HY6),1),1,TRUE,0)} | IC6: {=_xlfn.IFS($D6="","",AND(IA6=$C6,IB6=$D6),3,($C6-$D6)/MAX(ABS($C6-$D6),1)=(IA6-IB6)/MAX(ABS(IA6-IB6),1),1,TRUE,0)} | IF6: {=_xlfn.IFS($D6="","",AND(ID6=$C6,IE6=$D6),3,($C6-$D6)/MAX(ABS($C6-$D6),1)=(ID6-IE6)/MAX(ABS(ID6-IE6),1),1,TRUE,0)} | II6: {=_xlfn.IFS($D6="","",AND(IG6=$C6,IH6=$D6),3,($C6-$D6)/MAX(ABS($C6-$D6),1)=(IG6-IH6)/MAX(ABS(IG6-IH6),1),1,TRUE,0)} | IL6: {=_xlfn.IFS($D6="","",AND(IJ6=$C6,IK6=$D6),3,($C6-$D6)/MAX(ABS($C6-$D6),1)=(IJ6-IK6)/MAX(ABS(IJ6-IK6),1),1,TRUE,0)} | IO6: {=_xlfn.IFS($D6="","",AND(IM6=$C6,IN6=$D6),3,($C6-$D6)/MAX(ABS($C6-$D6),1)=(IM6-IN6)/MAX(ABS(IM6-IN6),1),1,TRUE,0)} | IR6: {=_xlfn.IFS($D6="","",AND(IP6=$C6,IQ6=$D6),3,($C6-$D6)/MAX(ABS($C6-$D6),1)=(IP6-IQ6)/MAX(ABS(IP6-IQ6),1),1,TRUE,0)} | IU6: {=_xlfn.IFS($D6="","",AND(IS6=$C6,IT6=$D6),3,($C6-$D6)/MAX(ABS($C6-$D6),1)=(IS6-IT6)/MAX(ABS(IS6-IT6),1),1,TRUE,0)} | IX6: {=_xlfn.IFS($D6="","",AND(IV6=$C6,IW6=$D6),3,($C6-$D6)/MAX(ABS($C6-$D6),1)=(IV6-IW6)/MAX(ABS(IV6-IW6),1),1,TRUE,0)} | JA6: {=_xlfn.IFS($D6="","",AND(IY6=$C6,IZ6=$D6),3,($C6-$D6)/MAX(ABS($C6-$D6),1)=(IY6-IZ6)/MAX(ABS(IY6-IZ6),1),1,TRUE,0)} | JD6: {=_xlfn.IFS($D6="","",AND(JB6=$C6,JC6=$D6),3,($C6-$D6)/MAX(ABS($C6-$D6),1)=(JB6-JC6)/MAX(ABS(JB6-JC6),1),1,TRUE,0)}
